[2022-10-10 15:56:32,929][flower.events.run():199] [ERROR] Failed to capture events: 'Connection closed by server.', trying again in 1 seconds.
[2022-10-10 15:56:37,792][root.__registerBeatThreadRun():162] [ERROR] 服务心跳维持失败！
Traceback (most recent call last):
  File "/usr/local/python3/lib/python3.9/site-packages/urllib3/connectionpool.py", line 699, in urlopen
    httplib_response = self._make_request(
  File "/usr/local/python3/lib/python3.9/site-packages/urllib3/connectionpool.py", line 445, in _make_request
    six.raise_from(e, None)
  File "<string>", line 3, in raise_from
  File "/usr/local/python3/lib/python3.9/site-packages/urllib3/connectionpool.py", line 440, in _make_request
    httplib_response = conn.getresponse()
  File "/usr/local/python3/lib/python3.9/http/client.py", line 1377, in getresponse
    response.begin()
  File "/usr/local/python3/lib/python3.9/http/client.py", line 320, in begin
    version, status, reason = self._read_status()
  File "/usr/local/python3/lib/python3.9/http/client.py", line 281, in _read_status
    line = str(self.fp.readline(_MAXLINE + 1), "iso-8859-1")
  File "/usr/local/python3/lib/python3.9/socket.py", line 704, in readinto
    return self._sock.recv_into(b)
ConnectionResetError: [Errno 104] Connection reset by peer

During handling of the above exception, another exception occurred:

Traceback (most recent call last):
  File "/usr/local/python3/lib/python3.9/site-packages/requests/adapters.py", line 489, in send
    resp = conn.urlopen(
  File "/usr/local/python3/lib/python3.9/site-packages/urllib3/connectionpool.py", line 755, in urlopen
    retries = retries.increment(
  File "/usr/local/python3/lib/python3.9/site-packages/urllib3/util/retry.py", line 532, in increment
    raise six.reraise(type(error), error, _stacktrace)
  File "/usr/local/python3/lib/python3.9/site-packages/urllib3/packages/six.py", line 769, in reraise
    raise value.with_traceback(tb)
  File "/usr/local/python3/lib/python3.9/site-packages/urllib3/connectionpool.py", line 699, in urlopen
    httplib_response = self._make_request(
  File "/usr/local/python3/lib/python3.9/site-packages/urllib3/connectionpool.py", line 445, in _make_request
    six.raise_from(e, None)
  File "<string>", line 3, in raise_from
  File "/usr/local/python3/lib/python3.9/site-packages/urllib3/connectionpool.py", line 440, in _make_request
    httplib_response = conn.getresponse()
  File "/usr/local/python3/lib/python3.9/http/client.py", line 1377, in getresponse
    response.begin()
  File "/usr/local/python3/lib/python3.9/http/client.py", line 320, in begin
    version, status, reason = self._read_status()
  File "/usr/local/python3/lib/python3.9/http/client.py", line 281, in _read_status
    line = str(self.fp.readline(_MAXLINE + 1), "iso-8859-1")
  File "/usr/local/python3/lib/python3.9/socket.py", line 704, in readinto
    return self._sock.recv_into(b)
urllib3.exceptions.ProtocolError: ('Connection aborted.', ConnectionResetError(104, 'Connection reset by peer'))

During handling of the above exception, another exception occurred:

Traceback (most recent call last):
  File "/usr/local/python3/lib/python3.9/site-packages/KcangNacos/nacos.py", line 153, in __registerBeatThreadRun
    re = requests.put(beatUrl[:-1])
  File "/usr/local/python3/lib/python3.9/site-packages/requests/api.py", line 130, in put
    return request("put", url, data=data, **kwargs)
  File "/usr/local/python3/lib/python3.9/site-packages/requests/api.py", line 59, in request
    return session.request(method=method, url=url, **kwargs)
  File "/usr/local/python3/lib/python3.9/site-packages/requests/sessions.py", line 587, in request
    resp = self.send(prep, **send_kwargs)
  File "/usr/local/python3/lib/python3.9/site-packages/requests/sessions.py", line 701, in send
    r = adapter.send(request, **kwargs)
  File "/usr/local/python3/lib/python3.9/site-packages/requests/adapters.py", line 547, in send
    raise ConnectionError(err, request=request)
requests.exceptions.ConnectionError: ('Connection aborted.', ConnectionResetError(104, 'Connection reset by peer'))
[2022-10-10 15:56:37,795][root.__registerBeatThreadRun():162] [ERROR] 服务心跳维持失败！
Traceback (most recent call last):
  File "/usr/local/python3/lib/python3.9/site-packages/urllib3/connectionpool.py", line 699, in urlopen
    httplib_response = self._make_request(
  File "/usr/local/python3/lib/python3.9/site-packages/urllib3/connectionpool.py", line 445, in _make_request
    six.raise_from(e, None)
  File "<string>", line 3, in raise_from
  File "/usr/local/python3/lib/python3.9/site-packages/urllib3/connectionpool.py", line 440, in _make_request
    httplib_response = conn.getresponse()
  File "/usr/local/python3/lib/python3.9/http/client.py", line 1377, in getresponse
    response.begin()
  File "/usr/local/python3/lib/python3.9/http/client.py", line 320, in begin
    version, status, reason = self._read_status()
  File "/usr/local/python3/lib/python3.9/http/client.py", line 289, in _read_status
    raise RemoteDisconnected("Remote end closed connection without"
http.client.RemoteDisconnected: Remote end closed connection without response

During handling of the above exception, another exception occurred:

Traceback (most recent call last):
  File "/usr/local/python3/lib/python3.9/site-packages/requests/adapters.py", line 489, in send
    resp = conn.urlopen(
  File "/usr/local/python3/lib/python3.9/site-packages/urllib3/connectionpool.py", line 755, in urlopen
    retries = retries.increment(
  File "/usr/local/python3/lib/python3.9/site-packages/urllib3/util/retry.py", line 532, in increment
    raise six.reraise(type(error), error, _stacktrace)
  File "/usr/local/python3/lib/python3.9/site-packages/urllib3/packages/six.py", line 769, in reraise
    raise value.with_traceback(tb)
  File "/usr/local/python3/lib/python3.9/site-packages/urllib3/connectionpool.py", line 699, in urlopen
    httplib_response = self._make_request(
  File "/usr/local/python3/lib/python3.9/site-packages/urllib3/connectionpool.py", line 445, in _make_request
    six.raise_from(e, None)
  File "<string>", line 3, in raise_from
  File "/usr/local/python3/lib/python3.9/site-packages/urllib3/connectionpool.py", line 440, in _make_request
    httplib_response = conn.getresponse()
  File "/usr/local/python3/lib/python3.9/http/client.py", line 1377, in getresponse
    response.begin()
  File "/usr/local/python3/lib/python3.9/http/client.py", line 320, in begin
    version, status, reason = self._read_status()
  File "/usr/local/python3/lib/python3.9/http/client.py", line 289, in _read_status
    raise RemoteDisconnected("Remote end closed connection without"
urllib3.exceptions.ProtocolError: ('Connection aborted.', RemoteDisconnected('Remote end closed connection without response'))

During handling of the above exception, another exception occurred:

Traceback (most recent call last):
  File "/usr/local/python3/lib/python3.9/site-packages/KcangNacos/nacos.py", line 153, in __registerBeatThreadRun
    re = requests.put(beatUrl[:-1])
  File "/usr/local/python3/lib/python3.9/site-packages/requests/api.py", line 130, in put
    return request("put", url, data=data, **kwargs)
  File "/usr/local/python3/lib/python3.9/site-packages/requests/api.py", line 59, in request
    return session.request(method=method, url=url, **kwargs)
  File "/usr/local/python3/lib/python3.9/site-packages/requests/sessions.py", line 587, in request
    resp = self.send(prep, **send_kwargs)
  File "/usr/local/python3/lib/python3.9/site-packages/requests/sessions.py", line 701, in send
    r = adapter.send(request, **kwargs)
  File "/usr/local/python3/lib/python3.9/site-packages/requests/adapters.py", line 547, in send
    raise ConnectionError(err, request=request)
requests.exceptions.ConnectionError: ('Connection aborted.', RemoteDisconnected('Remote end closed connection without response'))
[2022-10-10 15:59:51,401][flower.events.run():199] [ERROR] Failed to capture events: 'Connection closed by server.', trying again in 1 seconds.
[2022-10-10 15:59:52,097][root.__registerBeatThreadRun():162] [ERROR] 服务心跳维持失败！
Traceback (most recent call last):
  File "/usr/local/python3/lib/python3.9/site-packages/urllib3/connectionpool.py", line 699, in urlopen
    httplib_response = self._make_request(
  File "/usr/local/python3/lib/python3.9/site-packages/urllib3/connectionpool.py", line 445, in _make_request
    six.raise_from(e, None)
  File "<string>", line 3, in raise_from
  File "/usr/local/python3/lib/python3.9/site-packages/urllib3/connectionpool.py", line 440, in _make_request
    httplib_response = conn.getresponse()
  File "/usr/local/python3/lib/python3.9/http/client.py", line 1377, in getresponse
    response.begin()
  File "/usr/local/python3/lib/python3.9/http/client.py", line 320, in begin
    version, status, reason = self._read_status()
  File "/usr/local/python3/lib/python3.9/http/client.py", line 281, in _read_status
    line = str(self.fp.readline(_MAXLINE + 1), "iso-8859-1")
  File "/usr/local/python3/lib/python3.9/socket.py", line 704, in readinto
    return self._sock.recv_into(b)
ConnectionResetError: [Errno 104] Connection reset by peer

During handling of the above exception, another exception occurred:

Traceback (most recent call last):
  File "/usr/local/python3/lib/python3.9/site-packages/requests/adapters.py", line 489, in send
    resp = conn.urlopen(
  File "/usr/local/python3/lib/python3.9/site-packages/urllib3/connectionpool.py", line 755, in urlopen
    retries = retries.increment(
  File "/usr/local/python3/lib/python3.9/site-packages/urllib3/util/retry.py", line 532, in increment
    raise six.reraise(type(error), error, _stacktrace)
  File "/usr/local/python3/lib/python3.9/site-packages/urllib3/packages/six.py", line 769, in reraise
    raise value.with_traceback(tb)
  File "/usr/local/python3/lib/python3.9/site-packages/urllib3/connectionpool.py", line 699, in urlopen
    httplib_response = self._make_request(
  File "/usr/local/python3/lib/python3.9/site-packages/urllib3/connectionpool.py", line 445, in _make_request
    six.raise_from(e, None)
  File "<string>", line 3, in raise_from
  File "/usr/local/python3/lib/python3.9/site-packages/urllib3/connectionpool.py", line 440, in _make_request
    httplib_response = conn.getresponse()
  File "/usr/local/python3/lib/python3.9/http/client.py", line 1377, in getresponse
    response.begin()
  File "/usr/local/python3/lib/python3.9/http/client.py", line 320, in begin
    version, status, reason = self._read_status()
  File "/usr/local/python3/lib/python3.9/http/client.py", line 281, in _read_status
    line = str(self.fp.readline(_MAXLINE + 1), "iso-8859-1")
  File "/usr/local/python3/lib/python3.9/socket.py", line 704, in readinto
    return self._sock.recv_into(b)
urllib3.exceptions.ProtocolError: ('Connection aborted.', ConnectionResetError(104, 'Connection reset by peer'))

During handling of the above exception, another exception occurred:

Traceback (most recent call last):
  File "/usr/local/python3/lib/python3.9/site-packages/KcangNacos/nacos.py", line 153, in __registerBeatThreadRun
    re = requests.put(beatUrl[:-1])
  File "/usr/local/python3/lib/python3.9/site-packages/requests/api.py", line 130, in put
    return request("put", url, data=data, **kwargs)
  File "/usr/local/python3/lib/python3.9/site-packages/requests/api.py", line 59, in request
    return session.request(method=method, url=url, **kwargs)
  File "/usr/local/python3/lib/python3.9/site-packages/requests/sessions.py", line 587, in request
    resp = self.send(prep, **send_kwargs)
  File "/usr/local/python3/lib/python3.9/site-packages/requests/sessions.py", line 701, in send
    r = adapter.send(request, **kwargs)
  File "/usr/local/python3/lib/python3.9/site-packages/requests/adapters.py", line 547, in send
    raise ConnectionError(err, request=request)
requests.exceptions.ConnectionError: ('Connection aborted.', ConnectionResetError(104, 'Connection reset by peer'))
[2022-10-10 15:59:52,100][root.__registerBeatThreadRun():162] [ERROR] 服务心跳维持失败！
Traceback (most recent call last):
  File "/usr/local/python3/lib/python3.9/site-packages/urllib3/connectionpool.py", line 699, in urlopen
    httplib_response = self._make_request(
  File "/usr/local/python3/lib/python3.9/site-packages/urllib3/connectionpool.py", line 445, in _make_request
    six.raise_from(e, None)
  File "<string>", line 3, in raise_from
  File "/usr/local/python3/lib/python3.9/site-packages/urllib3/connectionpool.py", line 440, in _make_request
    httplib_response = conn.getresponse()
  File "/usr/local/python3/lib/python3.9/http/client.py", line 1377, in getresponse
    response.begin()
  File "/usr/local/python3/lib/python3.9/http/client.py", line 320, in begin
    version, status, reason = self._read_status()
  File "/usr/local/python3/lib/python3.9/http/client.py", line 281, in _read_status
    line = str(self.fp.readline(_MAXLINE + 1), "iso-8859-1")
  File "/usr/local/python3/lib/python3.9/socket.py", line 704, in readinto
    return self._sock.recv_into(b)
ConnectionResetError: [Errno 104] Connection reset by peer

During handling of the above exception, another exception occurred:

Traceback (most recent call last):
  File "/usr/local/python3/lib/python3.9/site-packages/requests/adapters.py", line 489, in send
    resp = conn.urlopen(
  File "/usr/local/python3/lib/python3.9/site-packages/urllib3/connectionpool.py", line 755, in urlopen
    retries = retries.increment(
  File "/usr/local/python3/lib/python3.9/site-packages/urllib3/util/retry.py", line 532, in increment
    raise six.reraise(type(error), error, _stacktrace)
  File "/usr/local/python3/lib/python3.9/site-packages/urllib3/packages/six.py", line 769, in reraise
    raise value.with_traceback(tb)
  File "/usr/local/python3/lib/python3.9/site-packages/urllib3/connectionpool.py", line 699, in urlopen
    httplib_response = self._make_request(
  File "/usr/local/python3/lib/python3.9/site-packages/urllib3/connectionpool.py", line 445, in _make_request
    six.raise_from(e, None)
  File "<string>", line 3, in raise_from
  File "/usr/local/python3/lib/python3.9/site-packages/urllib3/connectionpool.py", line 440, in _make_request
    httplib_response = conn.getresponse()
  File "/usr/local/python3/lib/python3.9/http/client.py", line 1377, in getresponse
    response.begin()
  File "/usr/local/python3/lib/python3.9/http/client.py", line 320, in begin
    version, status, reason = self._read_status()
  File "/usr/local/python3/lib/python3.9/http/client.py", line 281, in _read_status
    line = str(self.fp.readline(_MAXLINE + 1), "iso-8859-1")
  File "/usr/local/python3/lib/python3.9/socket.py", line 704, in readinto
    return self._sock.recv_into(b)
urllib3.exceptions.ProtocolError: ('Connection aborted.', ConnectionResetError(104, 'Connection reset by peer'))

During handling of the above exception, another exception occurred:

Traceback (most recent call last):
  File "/usr/local/python3/lib/python3.9/site-packages/KcangNacos/nacos.py", line 153, in __registerBeatThreadRun
    re = requests.put(beatUrl[:-1])
  File "/usr/local/python3/lib/python3.9/site-packages/requests/api.py", line 130, in put
    return request("put", url, data=data, **kwargs)
  File "/usr/local/python3/lib/python3.9/site-packages/requests/api.py", line 59, in request
    return session.request(method=method, url=url, **kwargs)
  File "/usr/local/python3/lib/python3.9/site-packages/requests/sessions.py", line 587, in request
    resp = self.send(prep, **send_kwargs)
  File "/usr/local/python3/lib/python3.9/site-packages/requests/sessions.py", line 701, in send
    r = adapter.send(request, **kwargs)
  File "/usr/local/python3/lib/python3.9/site-packages/requests/adapters.py", line 547, in send
    raise ConnectionError(err, request=request)
requests.exceptions.ConnectionError: ('Connection aborted.', ConnectionResetError(104, 'Connection reset by peer'))
[2022-10-10 16:03:48,114][flower.events.run():199] [ERROR] Failed to capture events: 'Connection closed by server.', trying again in 1 seconds.
[2022-10-10 16:03:51,837][root.__registerBeatThreadRun():162] [ERROR] 服务心跳维持失败！
Traceback (most recent call last):
  File "/usr/local/python3/lib/python3.9/site-packages/urllib3/connectionpool.py", line 699, in urlopen
    httplib_response = self._make_request(
  File "/usr/local/python3/lib/python3.9/site-packages/urllib3/connectionpool.py", line 445, in _make_request
    six.raise_from(e, None)
  File "<string>", line 3, in raise_from
  File "/usr/local/python3/lib/python3.9/site-packages/urllib3/connectionpool.py", line 440, in _make_request
    httplib_response = conn.getresponse()
  File "/usr/local/python3/lib/python3.9/http/client.py", line 1377, in getresponse
    response.begin()
  File "/usr/local/python3/lib/python3.9/http/client.py", line 320, in begin
    version, status, reason = self._read_status()
  File "/usr/local/python3/lib/python3.9/http/client.py", line 281, in _read_status
    line = str(self.fp.readline(_MAXLINE + 1), "iso-8859-1")
  File "/usr/local/python3/lib/python3.9/socket.py", line 704, in readinto
    return self._sock.recv_into(b)
ConnectionResetError: [Errno 104] Connection reset by peer

During handling of the above exception, another exception occurred:

Traceback (most recent call last):
  File "/usr/local/python3/lib/python3.9/site-packages/requests/adapters.py", line 489, in send
    resp = conn.urlopen(
  File "/usr/local/python3/lib/python3.9/site-packages/urllib3/connectionpool.py", line 755, in urlopen
    retries = retries.increment(
  File "/usr/local/python3/lib/python3.9/site-packages/urllib3/util/retry.py", line 532, in increment
    raise six.reraise(type(error), error, _stacktrace)
  File "/usr/local/python3/lib/python3.9/site-packages/urllib3/packages/six.py", line 769, in reraise
    raise value.with_traceback(tb)
  File "/usr/local/python3/lib/python3.9/site-packages/urllib3/connectionpool.py", line 699, in urlopen
    httplib_response = self._make_request(
  File "/usr/local/python3/lib/python3.9/site-packages/urllib3/connectionpool.py", line 445, in _make_request
    six.raise_from(e, None)
  File "<string>", line 3, in raise_from
  File "/usr/local/python3/lib/python3.9/site-packages/urllib3/connectionpool.py", line 440, in _make_request
    httplib_response = conn.getresponse()
  File "/usr/local/python3/lib/python3.9/http/client.py", line 1377, in getresponse
    response.begin()
  File "/usr/local/python3/lib/python3.9/http/client.py", line 320, in begin
    version, status, reason = self._read_status()
  File "/usr/local/python3/lib/python3.9/http/client.py", line 281, in _read_status
    line = str(self.fp.readline(_MAXLINE + 1), "iso-8859-1")
  File "/usr/local/python3/lib/python3.9/socket.py", line 704, in readinto
    return self._sock.recv_into(b)
urllib3.exceptions.ProtocolError: ('Connection aborted.', ConnectionResetError(104, 'Connection reset by peer'))

During handling of the above exception, another exception occurred:

Traceback (most recent call last):
  File "/usr/local/python3/lib/python3.9/site-packages/KcangNacos/nacos.py", line 153, in __registerBeatThreadRun
    re = requests.put(beatUrl[:-1])
  File "/usr/local/python3/lib/python3.9/site-packages/requests/api.py", line 130, in put
    return request("put", url, data=data, **kwargs)
  File "/usr/local/python3/lib/python3.9/site-packages/requests/api.py", line 59, in request
    return session.request(method=method, url=url, **kwargs)
  File "/usr/local/python3/lib/python3.9/site-packages/requests/sessions.py", line 587, in request
    resp = self.send(prep, **send_kwargs)
  File "/usr/local/python3/lib/python3.9/site-packages/requests/sessions.py", line 701, in send
    r = adapter.send(request, **kwargs)
  File "/usr/local/python3/lib/python3.9/site-packages/requests/adapters.py", line 547, in send
    raise ConnectionError(err, request=request)
requests.exceptions.ConnectionError: ('Connection aborted.', ConnectionResetError(104, 'Connection reset by peer'))
[2022-10-10 16:03:51,845][root.__registerBeatThreadRun():162] [ERROR] 服务心跳维持失败！
Traceback (most recent call last):
  File "/usr/local/python3/lib/python3.9/site-packages/urllib3/connectionpool.py", line 699, in urlopen
    httplib_response = self._make_request(
  File "/usr/local/python3/lib/python3.9/site-packages/urllib3/connectionpool.py", line 445, in _make_request
    six.raise_from(e, None)
  File "<string>", line 3, in raise_from
  File "/usr/local/python3/lib/python3.9/site-packages/urllib3/connectionpool.py", line 440, in _make_request
    httplib_response = conn.getresponse()
  File "/usr/local/python3/lib/python3.9/http/client.py", line 1377, in getresponse
    response.begin()
  File "/usr/local/python3/lib/python3.9/http/client.py", line 320, in begin
    version, status, reason = self._read_status()
  File "/usr/local/python3/lib/python3.9/http/client.py", line 281, in _read_status
    line = str(self.fp.readline(_MAXLINE + 1), "iso-8859-1")
  File "/usr/local/python3/lib/python3.9/socket.py", line 704, in readinto
    return self._sock.recv_into(b)
ConnectionResetError: [Errno 104] Connection reset by peer

During handling of the above exception, another exception occurred:

Traceback (most recent call last):
  File "/usr/local/python3/lib/python3.9/site-packages/requests/adapters.py", line 489, in send
    resp = conn.urlopen(
  File "/usr/local/python3/lib/python3.9/site-packages/urllib3/connectionpool.py", line 755, in urlopen
    retries = retries.increment(
  File "/usr/local/python3/lib/python3.9/site-packages/urllib3/util/retry.py", line 532, in increment
    raise six.reraise(type(error), error, _stacktrace)
  File "/usr/local/python3/lib/python3.9/site-packages/urllib3/packages/six.py", line 769, in reraise
    raise value.with_traceback(tb)
  File "/usr/local/python3/lib/python3.9/site-packages/urllib3/connectionpool.py", line 699, in urlopen
    httplib_response = self._make_request(
  File "/usr/local/python3/lib/python3.9/site-packages/urllib3/connectionpool.py", line 445, in _make_request
    six.raise_from(e, None)
  File "<string>", line 3, in raise_from
  File "/usr/local/python3/lib/python3.9/site-packages/urllib3/connectionpool.py", line 440, in _make_request
    httplib_response = conn.getresponse()
  File "/usr/local/python3/lib/python3.9/http/client.py", line 1377, in getresponse
    response.begin()
  File "/usr/local/python3/lib/python3.9/http/client.py", line 320, in begin
    version, status, reason = self._read_status()
  File "/usr/local/python3/lib/python3.9/http/client.py", line 281, in _read_status
    line = str(self.fp.readline(_MAXLINE + 1), "iso-8859-1")
  File "/usr/local/python3/lib/python3.9/socket.py", line 704, in readinto
    return self._sock.recv_into(b)
urllib3.exceptions.ProtocolError: ('Connection aborted.', ConnectionResetError(104, 'Connection reset by peer'))

During handling of the above exception, another exception occurred:

Traceback (most recent call last):
  File "/usr/local/python3/lib/python3.9/site-packages/KcangNacos/nacos.py", line 153, in __registerBeatThreadRun
    re = requests.put(beatUrl[:-1])
  File "/usr/local/python3/lib/python3.9/site-packages/requests/api.py", line 130, in put
    return request("put", url, data=data, **kwargs)
  File "/usr/local/python3/lib/python3.9/site-packages/requests/api.py", line 59, in request
    return session.request(method=method, url=url, **kwargs)
  File "/usr/local/python3/lib/python3.9/site-packages/requests/sessions.py", line 587, in request
    resp = self.send(prep, **send_kwargs)
  File "/usr/local/python3/lib/python3.9/site-packages/requests/sessions.py", line 701, in send
    r = adapter.send(request, **kwargs)
  File "/usr/local/python3/lib/python3.9/site-packages/requests/adapters.py", line 547, in send
    raise ConnectionError(err, request=request)
requests.exceptions.ConnectionError: ('Connection aborted.', ConnectionResetError(104, 'Connection reset by peer'))
[2022-10-11 10:17:42,733][celery.utils.dispatch.signal.send():280] [ERROR] Signal handler <bound method DjangoFixup.on_import_modules of <celery.fixups.django.DjangoFixup object at 0x7fe4ae56b7c0>> raised: ImproperlyConfigured("Application labels aren't unique, duplicates: system")
Traceback (most recent call last):
  File "/usr/local/python3/lib/python3.9/site-packages/celery/utils/dispatch/signal.py", line 276, in send
    response = receiver(signal=self, sender=sender, **named)
  File "/usr/local/python3/lib/python3.9/site-packages/celery/fixups/django.py", line 82, in on_import_modules
    self.worker_fixup.validate_models()
  File "/usr/local/python3/lib/python3.9/site-packages/celery/fixups/django.py", line 120, in validate_models
    self.django_setup()
  File "/usr/local/python3/lib/python3.9/site-packages/celery/fixups/django.py", line 116, in django_setup
    django.setup()
  File "/usr/local/python3/lib/python3.9/site-packages/django/__init__.py", line 24, in setup
    apps.populate(settings.INSTALLED_APPS)
  File "/usr/local/python3/lib/python3.9/site-packages/django/apps/registry.py", line 93, in populate
    raise ImproperlyConfigured(
django.core.exceptions.ImproperlyConfigured: Application labels aren't unique, duplicates: system
[2022-10-11 10:17:42,735][celery.utils.dispatch.signal.send():280] [ERROR] Signal handler <bound method DjangoFixup.on_import_modules of <celery.fixups.django.DjangoFixup object at 0x7faefee54790>> raised: ImproperlyConfigured("Application labels aren't unique, duplicates: system")
Traceback (most recent call last):
  File "/usr/local/python3/lib/python3.9/site-packages/celery/utils/dispatch/signal.py", line 276, in send
    response = receiver(signal=self, sender=sender, **named)
  File "/usr/local/python3/lib/python3.9/site-packages/celery/fixups/django.py", line 82, in on_import_modules
    self.worker_fixup.validate_models()
  File "/usr/local/python3/lib/python3.9/site-packages/celery/fixups/django.py", line 120, in validate_models
    self.django_setup()
  File "/usr/local/python3/lib/python3.9/site-packages/celery/fixups/django.py", line 116, in django_setup
    django.setup()
  File "/usr/local/python3/lib/python3.9/site-packages/django/__init__.py", line 24, in setup
    apps.populate(settings.INSTALLED_APPS)
  File "/usr/local/python3/lib/python3.9/site-packages/django/apps/registry.py", line 93, in populate
    raise ImproperlyConfigured(
django.core.exceptions.ImproperlyConfigured: Application labels aren't unique, duplicates: system
[2022-10-11 10:17:42,741][celery.utils.dispatch.signal.send():280] [ERROR] Signal handler <promise@0x7fe4ae577f70 --> <bound method Celery._autodiscover_tasks of <Celery netboost at 0x7fe4aee84910>>> raised: AppRegistryNotReady("Apps aren't loaded yet.")
Traceback (most recent call last):
  File "/usr/local/python3/lib/python3.9/site-packages/celery/utils/dispatch/signal.py", line 276, in send
    response = receiver(signal=self, sender=sender, **named)
  File "/usr/local/python3/lib/python3.9/site-packages/vine/promises.py", line 160, in __call__
    return self.throw()
  File "/usr/local/python3/lib/python3.9/site-packages/vine/promises.py", line 157, in __call__
    retval = fun(*final_args, **final_kwargs)
  File "/usr/local/python3/lib/python3.9/site-packages/celery/app/base.py", line 688, in _autodiscover_tasks
    return self._autodiscover_tasks_from_names(packages, related_name)
  File "/usr/local/python3/lib/python3.9/site-packages/celery/app/base.py", line 694, in _autodiscover_tasks_from_names
    packages() if callable(packages) else packages, related_name,
  File "/home/netaxe/netboost/celery.py", line 46, in <lambda>
    app.autodiscover_tasks(lambda: [n.name for n in apps.get_app_configs()])
  File "/usr/local/python3/lib/python3.9/site-packages/django/apps/registry.py", line 145, in get_app_configs
    self.check_apps_ready()
  File "/usr/local/python3/lib/python3.9/site-packages/django/apps/registry.py", line 136, in check_apps_ready
    raise AppRegistryNotReady("Apps aren't loaded yet.")
django.core.exceptions.AppRegistryNotReady: Apps aren't loaded yet.
[2022-10-11 10:17:42,743][celery.utils.dispatch.signal.send():280] [ERROR] Signal handler <promise@0x7faefee5ff70 --> <bound method Celery._autodiscover_tasks of <Celery netboost at 0x7faeff76c8e0>>> raised: AppRegistryNotReady("Apps aren't loaded yet.")
Traceback (most recent call last):
  File "/usr/local/python3/lib/python3.9/site-packages/celery/utils/dispatch/signal.py", line 276, in send
    response = receiver(signal=self, sender=sender, **named)
  File "/usr/local/python3/lib/python3.9/site-packages/vine/promises.py", line 160, in __call__
    return self.throw()
  File "/usr/local/python3/lib/python3.9/site-packages/vine/promises.py", line 157, in __call__
    retval = fun(*final_args, **final_kwargs)
  File "/usr/local/python3/lib/python3.9/site-packages/celery/app/base.py", line 688, in _autodiscover_tasks
    return self._autodiscover_tasks_from_names(packages, related_name)
  File "/usr/local/python3/lib/python3.9/site-packages/celery/app/base.py", line 694, in _autodiscover_tasks_from_names
    packages() if callable(packages) else packages, related_name,
  File "/home/netaxe/netboost/celery.py", line 46, in <lambda>
    app.autodiscover_tasks(lambda: [n.name for n in apps.get_app_configs()])
  File "/usr/local/python3/lib/python3.9/site-packages/django/apps/registry.py", line 145, in get_app_configs
    self.check_apps_ready()
  File "/usr/local/python3/lib/python3.9/site-packages/django/apps/registry.py", line 136, in check_apps_ready
    raise AppRegistryNotReady("Apps aren't loaded yet.")
django.core.exceptions.AppRegistryNotReady: Apps aren't loaded yet.
[2022-10-11 10:17:49,215][celery.utils.dispatch.signal.send():280] [ERROR] Signal handler <bound method DjangoFixup.on_import_modules of <celery.fixups.django.DjangoFixup object at 0x7fb3121d57c0>> raised: ImproperlyConfigured("Application labels aren't unique, duplicates: system")
Traceback (most recent call last):
  File "/usr/local/python3/lib/python3.9/site-packages/celery/utils/dispatch/signal.py", line 276, in send
    response = receiver(signal=self, sender=sender, **named)
  File "/usr/local/python3/lib/python3.9/site-packages/celery/fixups/django.py", line 82, in on_import_modules
    self.worker_fixup.validate_models()
  File "/usr/local/python3/lib/python3.9/site-packages/celery/fixups/django.py", line 120, in validate_models
    self.django_setup()
  File "/usr/local/python3/lib/python3.9/site-packages/celery/fixups/django.py", line 116, in django_setup
    django.setup()
  File "/usr/local/python3/lib/python3.9/site-packages/django/__init__.py", line 24, in setup
    apps.populate(settings.INSTALLED_APPS)
  File "/usr/local/python3/lib/python3.9/site-packages/django/apps/registry.py", line 93, in populate
    raise ImproperlyConfigured(
django.core.exceptions.ImproperlyConfigured: Application labels aren't unique, duplicates: system
[2022-10-11 10:17:49,218][celery.utils.dispatch.signal.send():280] [ERROR] Signal handler <promise@0x7fb3121dff70 --> <bound method Celery._autodiscover_tasks of <Celery netboost at 0x7fb312aec910>>> raised: AppRegistryNotReady("Apps aren't loaded yet.")
Traceback (most recent call last):
  File "/usr/local/python3/lib/python3.9/site-packages/celery/utils/dispatch/signal.py", line 276, in send
    response = receiver(signal=self, sender=sender, **named)
  File "/usr/local/python3/lib/python3.9/site-packages/vine/promises.py", line 160, in __call__
    return self.throw()
  File "/usr/local/python3/lib/python3.9/site-packages/vine/promises.py", line 157, in __call__
    retval = fun(*final_args, **final_kwargs)
  File "/usr/local/python3/lib/python3.9/site-packages/celery/app/base.py", line 688, in _autodiscover_tasks
    return self._autodiscover_tasks_from_names(packages, related_name)
  File "/usr/local/python3/lib/python3.9/site-packages/celery/app/base.py", line 694, in _autodiscover_tasks_from_names
    packages() if callable(packages) else packages, related_name,
  File "/home/netaxe/netboost/celery.py", line 46, in <lambda>
    app.autodiscover_tasks(lambda: [n.name for n in apps.get_app_configs()])
  File "/usr/local/python3/lib/python3.9/site-packages/django/apps/registry.py", line 145, in get_app_configs
    self.check_apps_ready()
  File "/usr/local/python3/lib/python3.9/site-packages/django/apps/registry.py", line 136, in check_apps_ready
    raise AppRegistryNotReady("Apps aren't loaded yet.")
django.core.exceptions.AppRegistryNotReady: Apps aren't loaded yet.
[2022-10-11 10:17:49,861][celery.utils.dispatch.signal.send():280] [ERROR] Signal handler <bound method DjangoFixup.on_import_modules of <celery.fixups.django.DjangoFixup object at 0x7ff48cd1e7c0>> raised: ImproperlyConfigured("Application labels aren't unique, duplicates: system")
Traceback (most recent call last):
  File "/usr/local/python3/lib/python3.9/site-packages/celery/utils/dispatch/signal.py", line 276, in send
    response = receiver(signal=self, sender=sender, **named)
  File "/usr/local/python3/lib/python3.9/site-packages/celery/fixups/django.py", line 82, in on_import_modules
    self.worker_fixup.validate_models()
  File "/usr/local/python3/lib/python3.9/site-packages/celery/fixups/django.py", line 120, in validate_models
    self.django_setup()
  File "/usr/local/python3/lib/python3.9/site-packages/celery/fixups/django.py", line 116, in django_setup
    django.setup()
  File "/usr/local/python3/lib/python3.9/site-packages/django/__init__.py", line 24, in setup
    apps.populate(settings.INSTALLED_APPS)
  File "/usr/local/python3/lib/python3.9/site-packages/django/apps/registry.py", line 93, in populate
    raise ImproperlyConfigured(
django.core.exceptions.ImproperlyConfigured: Application labels aren't unique, duplicates: system
[2022-10-11 10:17:49,862][celery.utils.dispatch.signal.send():280] [ERROR] Signal handler <promise@0x7ff48cd29f70 --> <bound method Celery._autodiscover_tasks of <Celery netboost at 0x7ff48d635910>>> raised: AppRegistryNotReady("Apps aren't loaded yet.")
Traceback (most recent call last):
  File "/usr/local/python3/lib/python3.9/site-packages/celery/utils/dispatch/signal.py", line 276, in send
    response = receiver(signal=self, sender=sender, **named)
  File "/usr/local/python3/lib/python3.9/site-packages/vine/promises.py", line 160, in __call__
    return self.throw()
  File "/usr/local/python3/lib/python3.9/site-packages/vine/promises.py", line 157, in __call__
    retval = fun(*final_args, **final_kwargs)
  File "/usr/local/python3/lib/python3.9/site-packages/celery/app/base.py", line 688, in _autodiscover_tasks
    return self._autodiscover_tasks_from_names(packages, related_name)
  File "/usr/local/python3/lib/python3.9/site-packages/celery/app/base.py", line 694, in _autodiscover_tasks_from_names
    packages() if callable(packages) else packages, related_name,
  File "/home/netaxe/netboost/celery.py", line 46, in <lambda>
    app.autodiscover_tasks(lambda: [n.name for n in apps.get_app_configs()])
  File "/usr/local/python3/lib/python3.9/site-packages/django/apps/registry.py", line 145, in get_app_configs
    self.check_apps_ready()
  File "/usr/local/python3/lib/python3.9/site-packages/django/apps/registry.py", line 136, in check_apps_ready
    raise AppRegistryNotReady("Apps aren't loaded yet.")
django.core.exceptions.AppRegistryNotReady: Apps aren't loaded yet.
[2022-10-11 10:17:53,757][celery.utils.dispatch.signal.send():280] [ERROR] Signal handler <bound method DjangoFixup.on_import_modules of <celery.fixups.django.DjangoFixup object at 0x7f30e9d93760>> raised: ImproperlyConfigured("Application labels aren't unique, duplicates: system")
Traceback (most recent call last):
  File "/usr/local/python3/lib/python3.9/site-packages/celery/utils/dispatch/signal.py", line 276, in send
    response = receiver(signal=self, sender=sender, **named)
  File "/usr/local/python3/lib/python3.9/site-packages/celery/fixups/django.py", line 82, in on_import_modules
    self.worker_fixup.validate_models()
  File "/usr/local/python3/lib/python3.9/site-packages/celery/fixups/django.py", line 120, in validate_models
    self.django_setup()
  File "/usr/local/python3/lib/python3.9/site-packages/celery/fixups/django.py", line 116, in django_setup
    django.setup()
  File "/usr/local/python3/lib/python3.9/site-packages/django/__init__.py", line 24, in setup
    apps.populate(settings.INSTALLED_APPS)
  File "/usr/local/python3/lib/python3.9/site-packages/django/apps/registry.py", line 93, in populate
    raise ImproperlyConfigured(
django.core.exceptions.ImproperlyConfigured: Application labels aren't unique, duplicates: system
[2022-10-11 10:17:53,758][celery.utils.dispatch.signal.send():280] [ERROR] Signal handler <promise@0x7f30e9d9ef70 --> <bound method Celery._autodiscover_tasks of <Celery netboost at 0x7f30ea6ab8b0>>> raised: AppRegistryNotReady("Apps aren't loaded yet.")
Traceback (most recent call last):
  File "/usr/local/python3/lib/python3.9/site-packages/celery/utils/dispatch/signal.py", line 276, in send
    response = receiver(signal=self, sender=sender, **named)
  File "/usr/local/python3/lib/python3.9/site-packages/vine/promises.py", line 160, in __call__
    return self.throw()
  File "/usr/local/python3/lib/python3.9/site-packages/vine/promises.py", line 157, in __call__
    retval = fun(*final_args, **final_kwargs)
  File "/usr/local/python3/lib/python3.9/site-packages/celery/app/base.py", line 688, in _autodiscover_tasks
    return self._autodiscover_tasks_from_names(packages, related_name)
  File "/usr/local/python3/lib/python3.9/site-packages/celery/app/base.py", line 694, in _autodiscover_tasks_from_names
    packages() if callable(packages) else packages, related_name,
  File "/home/netaxe/netboost/celery.py", line 46, in <lambda>
    app.autodiscover_tasks(lambda: [n.name for n in apps.get_app_configs()])
  File "/usr/local/python3/lib/python3.9/site-packages/django/apps/registry.py", line 145, in get_app_configs
    self.check_apps_ready()
  File "/usr/local/python3/lib/python3.9/site-packages/django/apps/registry.py", line 136, in check_apps_ready
    raise AppRegistryNotReady("Apps aren't loaded yet.")
django.core.exceptions.AppRegistryNotReady: Apps aren't loaded yet.
[2022-10-11 10:17:53,989][celery.utils.dispatch.signal.send():280] [ERROR] Signal handler <bound method DjangoFixup.on_import_modules of <celery.fixups.django.DjangoFixup object at 0x7f36eb021760>> raised: ImproperlyConfigured("Application labels aren't unique, duplicates: system")
Traceback (most recent call last):
  File "/usr/local/python3/lib/python3.9/site-packages/celery/utils/dispatch/signal.py", line 276, in send
    response = receiver(signal=self, sender=sender, **named)
  File "/usr/local/python3/lib/python3.9/site-packages/celery/fixups/django.py", line 82, in on_import_modules
    self.worker_fixup.validate_models()
  File "/usr/local/python3/lib/python3.9/site-packages/celery/fixups/django.py", line 120, in validate_models
    self.django_setup()
  File "/usr/local/python3/lib/python3.9/site-packages/celery/fixups/django.py", line 116, in django_setup
    django.setup()
  File "/usr/local/python3/lib/python3.9/site-packages/django/__init__.py", line 24, in setup
    apps.populate(settings.INSTALLED_APPS)
  File "/usr/local/python3/lib/python3.9/site-packages/django/apps/registry.py", line 93, in populate
    raise ImproperlyConfigured(
django.core.exceptions.ImproperlyConfigured: Application labels aren't unique, duplicates: system
[2022-10-11 10:17:53,991][celery.utils.dispatch.signal.send():280] [ERROR] Signal handler <promise@0x7f36eb02cf70 --> <bound method Celery._autodiscover_tasks of <Celery netboost at 0x7f36eb9398b0>>> raised: AppRegistryNotReady("Apps aren't loaded yet.")
Traceback (most recent call last):
  File "/usr/local/python3/lib/python3.9/site-packages/celery/utils/dispatch/signal.py", line 276, in send
    response = receiver(signal=self, sender=sender, **named)
  File "/usr/local/python3/lib/python3.9/site-packages/vine/promises.py", line 160, in __call__
    return self.throw()
  File "/usr/local/python3/lib/python3.9/site-packages/vine/promises.py", line 157, in __call__
    retval = fun(*final_args, **final_kwargs)
  File "/usr/local/python3/lib/python3.9/site-packages/celery/app/base.py", line 688, in _autodiscover_tasks
    return self._autodiscover_tasks_from_names(packages, related_name)
  File "/usr/local/python3/lib/python3.9/site-packages/celery/app/base.py", line 694, in _autodiscover_tasks_from_names
    packages() if callable(packages) else packages, related_name,
  File "/home/netaxe/netboost/celery.py", line 46, in <lambda>
    app.autodiscover_tasks(lambda: [n.name for n in apps.get_app_configs()])
  File "/usr/local/python3/lib/python3.9/site-packages/django/apps/registry.py", line 145, in get_app_configs
    self.check_apps_ready()
  File "/usr/local/python3/lib/python3.9/site-packages/django/apps/registry.py", line 136, in check_apps_ready
    raise AppRegistryNotReady("Apps aren't loaded yet.")
django.core.exceptions.AppRegistryNotReady: Apps aren't loaded yet.
[2022-10-11 10:21:26,778][celery.utils.dispatch.signal.send():280] [ERROR] Signal handler <bound method DjangoFixup.on_import_modules of <celery.fixups.django.DjangoFixup object at 0x7f2466485790>> raised: ImproperlyConfigured("Application labels aren't unique, duplicates: system")
Traceback (most recent call last):
  File "/usr/local/python3/lib/python3.9/site-packages/celery/utils/dispatch/signal.py", line 276, in send
    response = receiver(signal=self, sender=sender, **named)
  File "/usr/local/python3/lib/python3.9/site-packages/celery/fixups/django.py", line 82, in on_import_modules
    self.worker_fixup.validate_models()
  File "/usr/local/python3/lib/python3.9/site-packages/celery/fixups/django.py", line 120, in validate_models
    self.django_setup()
  File "/usr/local/python3/lib/python3.9/site-packages/celery/fixups/django.py", line 116, in django_setup
    django.setup()
  File "/usr/local/python3/lib/python3.9/site-packages/django/__init__.py", line 24, in setup
    apps.populate(settings.INSTALLED_APPS)
  File "/usr/local/python3/lib/python3.9/site-packages/django/apps/registry.py", line 93, in populate
    raise ImproperlyConfigured(
django.core.exceptions.ImproperlyConfigured: Application labels aren't unique, duplicates: system
[2022-10-11 10:21:26,779][celery.utils.dispatch.signal.send():280] [ERROR] Signal handler <promise@0x7f2466490f70 --> <bound method Celery._autodiscover_tasks of <Celery netboost at 0x7f2466d9d8e0>>> raised: AppRegistryNotReady("Apps aren't loaded yet.")
Traceback (most recent call last):
  File "/usr/local/python3/lib/python3.9/site-packages/celery/utils/dispatch/signal.py", line 276, in send
    response = receiver(signal=self, sender=sender, **named)
  File "/usr/local/python3/lib/python3.9/site-packages/vine/promises.py", line 160, in __call__
    return self.throw()
  File "/usr/local/python3/lib/python3.9/site-packages/vine/promises.py", line 157, in __call__
    retval = fun(*final_args, **final_kwargs)
  File "/usr/local/python3/lib/python3.9/site-packages/celery/app/base.py", line 688, in _autodiscover_tasks
    return self._autodiscover_tasks_from_names(packages, related_name)
  File "/usr/local/python3/lib/python3.9/site-packages/celery/app/base.py", line 694, in _autodiscover_tasks_from_names
    packages() if callable(packages) else packages, related_name,
  File "/home/netaxe/netboost/celery.py", line 46, in <lambda>
    app.autodiscover_tasks(lambda: [n.name for n in apps.get_app_configs()])
  File "/usr/local/python3/lib/python3.9/site-packages/django/apps/registry.py", line 145, in get_app_configs
    self.check_apps_ready()
  File "/usr/local/python3/lib/python3.9/site-packages/django/apps/registry.py", line 136, in check_apps_ready
    raise AppRegistryNotReady("Apps aren't loaded yet.")
django.core.exceptions.AppRegistryNotReady: Apps aren't loaded yet.
[2022-10-11 10:21:26,793][celery.utils.dispatch.signal.send():280] [ERROR] Signal handler <bound method DjangoFixup.on_import_modules of <celery.fixups.django.DjangoFixup object at 0x7f8cfb2de7c0>> raised: ImproperlyConfigured("Application labels aren't unique, duplicates: system")
Traceback (most recent call last):
  File "/usr/local/python3/lib/python3.9/site-packages/celery/utils/dispatch/signal.py", line 276, in send
    response = receiver(signal=self, sender=sender, **named)
  File "/usr/local/python3/lib/python3.9/site-packages/celery/fixups/django.py", line 82, in on_import_modules
    self.worker_fixup.validate_models()
  File "/usr/local/python3/lib/python3.9/site-packages/celery/fixups/django.py", line 120, in validate_models
    self.django_setup()
  File "/usr/local/python3/lib/python3.9/site-packages/celery/fixups/django.py", line 116, in django_setup
    django.setup()
  File "/usr/local/python3/lib/python3.9/site-packages/django/__init__.py", line 24, in setup
    apps.populate(settings.INSTALLED_APPS)
  File "/usr/local/python3/lib/python3.9/site-packages/django/apps/registry.py", line 93, in populate
    raise ImproperlyConfigured(
django.core.exceptions.ImproperlyConfigured: Application labels aren't unique, duplicates: system
[2022-10-11 10:21:26,794][celery.utils.dispatch.signal.send():280] [ERROR] Signal handler <promise@0x7f8cfb2e8f70 --> <bound method Celery._autodiscover_tasks of <Celery netboost at 0x7f8cfbbf6910>>> raised: AppRegistryNotReady("Apps aren't loaded yet.")
Traceback (most recent call last):
  File "/usr/local/python3/lib/python3.9/site-packages/celery/utils/dispatch/signal.py", line 276, in send
    response = receiver(signal=self, sender=sender, **named)
  File "/usr/local/python3/lib/python3.9/site-packages/vine/promises.py", line 160, in __call__
    return self.throw()
  File "/usr/local/python3/lib/python3.9/site-packages/vine/promises.py", line 157, in __call__
    retval = fun(*final_args, **final_kwargs)
  File "/usr/local/python3/lib/python3.9/site-packages/celery/app/base.py", line 688, in _autodiscover_tasks
    return self._autodiscover_tasks_from_names(packages, related_name)
  File "/usr/local/python3/lib/python3.9/site-packages/celery/app/base.py", line 694, in _autodiscover_tasks_from_names
    packages() if callable(packages) else packages, related_name,
  File "/home/netaxe/netboost/celery.py", line 46, in <lambda>
    app.autodiscover_tasks(lambda: [n.name for n in apps.get_app_configs()])
  File "/usr/local/python3/lib/python3.9/site-packages/django/apps/registry.py", line 145, in get_app_configs
    self.check_apps_ready()
  File "/usr/local/python3/lib/python3.9/site-packages/django/apps/registry.py", line 136, in check_apps_ready
    raise AppRegistryNotReady("Apps aren't loaded yet.")
django.core.exceptions.AppRegistryNotReady: Apps aren't loaded yet.
[2022-10-11 10:21:35,102][celery.utils.dispatch.signal.send():280] [ERROR] Signal handler <bound method DjangoFixup.on_import_modules of <celery.fixups.django.DjangoFixup object at 0x7fef3b1b9760>> raised: ImproperlyConfigured("Application labels aren't unique, duplicates: system")
Traceback (most recent call last):
  File "/usr/local/python3/lib/python3.9/site-packages/celery/utils/dispatch/signal.py", line 276, in send
    response = receiver(signal=self, sender=sender, **named)
  File "/usr/local/python3/lib/python3.9/site-packages/celery/fixups/django.py", line 82, in on_import_modules
    self.worker_fixup.validate_models()
  File "/usr/local/python3/lib/python3.9/site-packages/celery/fixups/django.py", line 120, in validate_models
    self.django_setup()
  File "/usr/local/python3/lib/python3.9/site-packages/celery/fixups/django.py", line 116, in django_setup
    django.setup()
  File "/usr/local/python3/lib/python3.9/site-packages/django/__init__.py", line 24, in setup
    apps.populate(settings.INSTALLED_APPS)
  File "/usr/local/python3/lib/python3.9/site-packages/django/apps/registry.py", line 93, in populate
    raise ImproperlyConfigured(
django.core.exceptions.ImproperlyConfigured: Application labels aren't unique, duplicates: system
[2022-10-11 10:21:35,104][celery.utils.dispatch.signal.send():280] [ERROR] Signal handler <promise@0x7fef3b1c4f70 --> <bound method Celery._autodiscover_tasks of <Celery netboost at 0x7fef3bad18b0>>> raised: AppRegistryNotReady("Apps aren't loaded yet.")
Traceback (most recent call last):
  File "/usr/local/python3/lib/python3.9/site-packages/celery/utils/dispatch/signal.py", line 276, in send
    response = receiver(signal=self, sender=sender, **named)
  File "/usr/local/python3/lib/python3.9/site-packages/vine/promises.py", line 160, in __call__
    return self.throw()
  File "/usr/local/python3/lib/python3.9/site-packages/vine/promises.py", line 157, in __call__
    retval = fun(*final_args, **final_kwargs)
  File "/usr/local/python3/lib/python3.9/site-packages/celery/app/base.py", line 688, in _autodiscover_tasks
    return self._autodiscover_tasks_from_names(packages, related_name)
  File "/usr/local/python3/lib/python3.9/site-packages/celery/app/base.py", line 694, in _autodiscover_tasks_from_names
    packages() if callable(packages) else packages, related_name,
  File "/home/netaxe/netboost/celery.py", line 46, in <lambda>
    app.autodiscover_tasks(lambda: [n.name for n in apps.get_app_configs()])
  File "/usr/local/python3/lib/python3.9/site-packages/django/apps/registry.py", line 145, in get_app_configs
    self.check_apps_ready()
  File "/usr/local/python3/lib/python3.9/site-packages/django/apps/registry.py", line 136, in check_apps_ready
    raise AppRegistryNotReady("Apps aren't loaded yet.")
django.core.exceptions.AppRegistryNotReady: Apps aren't loaded yet.
[2022-10-11 10:21:35,253][celery.utils.dispatch.signal.send():280] [ERROR] Signal handler <bound method DjangoFixup.on_import_modules of <celery.fixups.django.DjangoFixup object at 0x7f725146c790>> raised: ImproperlyConfigured("Application labels aren't unique, duplicates: system")
Traceback (most recent call last):
  File "/usr/local/python3/lib/python3.9/site-packages/celery/utils/dispatch/signal.py", line 276, in send
    response = receiver(signal=self, sender=sender, **named)
  File "/usr/local/python3/lib/python3.9/site-packages/celery/fixups/django.py", line 82, in on_import_modules
    self.worker_fixup.validate_models()
  File "/usr/local/python3/lib/python3.9/site-packages/celery/fixups/django.py", line 120, in validate_models
    self.django_setup()
  File "/usr/local/python3/lib/python3.9/site-packages/celery/fixups/django.py", line 116, in django_setup
    django.setup()
  File "/usr/local/python3/lib/python3.9/site-packages/django/__init__.py", line 24, in setup
    apps.populate(settings.INSTALLED_APPS)
  File "/usr/local/python3/lib/python3.9/site-packages/django/apps/registry.py", line 93, in populate
    raise ImproperlyConfigured(
django.core.exceptions.ImproperlyConfigured: Application labels aren't unique, duplicates: system
[2022-10-11 10:21:35,255][celery.utils.dispatch.signal.send():280] [ERROR] Signal handler <promise@0x7f7251477f70 --> <bound method Celery._autodiscover_tasks of <Celery netboost at 0x7f7251d848e0>>> raised: AppRegistryNotReady("Apps aren't loaded yet.")
Traceback (most recent call last):
  File "/usr/local/python3/lib/python3.9/site-packages/celery/utils/dispatch/signal.py", line 276, in send
    response = receiver(signal=self, sender=sender, **named)
  File "/usr/local/python3/lib/python3.9/site-packages/vine/promises.py", line 160, in __call__
    return self.throw()
  File "/usr/local/python3/lib/python3.9/site-packages/vine/promises.py", line 157, in __call__
    retval = fun(*final_args, **final_kwargs)
  File "/usr/local/python3/lib/python3.9/site-packages/celery/app/base.py", line 688, in _autodiscover_tasks
    return self._autodiscover_tasks_from_names(packages, related_name)
  File "/usr/local/python3/lib/python3.9/site-packages/celery/app/base.py", line 694, in _autodiscover_tasks_from_names
    packages() if callable(packages) else packages, related_name,
  File "/home/netaxe/netboost/celery.py", line 46, in <lambda>
    app.autodiscover_tasks(lambda: [n.name for n in apps.get_app_configs()])
  File "/usr/local/python3/lib/python3.9/site-packages/django/apps/registry.py", line 145, in get_app_configs
    self.check_apps_ready()
  File "/usr/local/python3/lib/python3.9/site-packages/django/apps/registry.py", line 136, in check_apps_ready
    raise AppRegistryNotReady("Apps aren't loaded yet.")
django.core.exceptions.AppRegistryNotReady: Apps aren't loaded yet.
[2022-10-11 10:26:42,789][celery.utils.dispatch.signal.send():280] [ERROR] Signal handler <bound method DjangoFixup.on_import_modules of <celery.fixups.django.DjangoFixup object at 0x7f9984ae27c0>> raised: ImproperlyConfigured("Application labels aren't unique, duplicates: system")
Traceback (most recent call last):
  File "/usr/local/python3/lib/python3.9/site-packages/celery/utils/dispatch/signal.py", line 276, in send
    response = receiver(signal=self, sender=sender, **named)
  File "/usr/local/python3/lib/python3.9/site-packages/celery/fixups/django.py", line 82, in on_import_modules
    self.worker_fixup.validate_models()
  File "/usr/local/python3/lib/python3.9/site-packages/celery/fixups/django.py", line 120, in validate_models
    self.django_setup()
  File "/usr/local/python3/lib/python3.9/site-packages/celery/fixups/django.py", line 116, in django_setup
    django.setup()
  File "/usr/local/python3/lib/python3.9/site-packages/django/__init__.py", line 24, in setup
    apps.populate(settings.INSTALLED_APPS)
  File "/usr/local/python3/lib/python3.9/site-packages/django/apps/registry.py", line 93, in populate
    raise ImproperlyConfigured(
django.core.exceptions.ImproperlyConfigured: Application labels aren't unique, duplicates: system
[2022-10-11 10:26:42,790][celery.utils.dispatch.signal.send():280] [ERROR] Signal handler <promise@0x7f9984aeef70 --> <bound method Celery._autodiscover_tasks of <Celery netboost at 0x7f99853fb910>>> raised: AppRegistryNotReady("Apps aren't loaded yet.")
Traceback (most recent call last):
  File "/usr/local/python3/lib/python3.9/site-packages/celery/utils/dispatch/signal.py", line 276, in send
    response = receiver(signal=self, sender=sender, **named)
  File "/usr/local/python3/lib/python3.9/site-packages/vine/promises.py", line 160, in __call__
    return self.throw()
  File "/usr/local/python3/lib/python3.9/site-packages/vine/promises.py", line 157, in __call__
    retval = fun(*final_args, **final_kwargs)
  File "/usr/local/python3/lib/python3.9/site-packages/celery/app/base.py", line 688, in _autodiscover_tasks
    return self._autodiscover_tasks_from_names(packages, related_name)
  File "/usr/local/python3/lib/python3.9/site-packages/celery/app/base.py", line 694, in _autodiscover_tasks_from_names
    packages() if callable(packages) else packages, related_name,
  File "/home/netaxe/netboost/celery.py", line 46, in <lambda>
    app.autodiscover_tasks(lambda: [n.name for n in apps.get_app_configs()])
  File "/usr/local/python3/lib/python3.9/site-packages/django/apps/registry.py", line 145, in get_app_configs
    self.check_apps_ready()
  File "/usr/local/python3/lib/python3.9/site-packages/django/apps/registry.py", line 136, in check_apps_ready
    raise AppRegistryNotReady("Apps aren't loaded yet.")
django.core.exceptions.AppRegistryNotReady: Apps aren't loaded yet.
[2022-10-11 10:26:42,790][celery.utils.dispatch.signal.send():280] [ERROR] Signal handler <bound method DjangoFixup.on_import_modules of <celery.fixups.django.DjangoFixup object at 0x7f8c324d47c0>> raised: ImproperlyConfigured("Application labels aren't unique, duplicates: system")
Traceback (most recent call last):
  File "/usr/local/python3/lib/python3.9/site-packages/celery/utils/dispatch/signal.py", line 276, in send
    response = receiver(signal=self, sender=sender, **named)
  File "/usr/local/python3/lib/python3.9/site-packages/celery/fixups/django.py", line 82, in on_import_modules
    self.worker_fixup.validate_models()
  File "/usr/local/python3/lib/python3.9/site-packages/celery/fixups/django.py", line 120, in validate_models
    self.django_setup()
  File "/usr/local/python3/lib/python3.9/site-packages/celery/fixups/django.py", line 116, in django_setup
    django.setup()
  File "/usr/local/python3/lib/python3.9/site-packages/django/__init__.py", line 24, in setup
    apps.populate(settings.INSTALLED_APPS)
  File "/usr/local/python3/lib/python3.9/site-packages/django/apps/registry.py", line 93, in populate
    raise ImproperlyConfigured(
django.core.exceptions.ImproperlyConfigured: Application labels aren't unique, duplicates: system
[2022-10-11 10:26:42,794][celery.utils.dispatch.signal.send():280] [ERROR] Signal handler <promise@0x7f8c324def70 --> <bound method Celery._autodiscover_tasks of <Celery netboost at 0x7f8c32deb910>>> raised: AppRegistryNotReady("Apps aren't loaded yet.")
Traceback (most recent call last):
  File "/usr/local/python3/lib/python3.9/site-packages/celery/utils/dispatch/signal.py", line 276, in send
    response = receiver(signal=self, sender=sender, **named)
  File "/usr/local/python3/lib/python3.9/site-packages/vine/promises.py", line 160, in __call__
    return self.throw()
  File "/usr/local/python3/lib/python3.9/site-packages/vine/promises.py", line 157, in __call__
    retval = fun(*final_args, **final_kwargs)
  File "/usr/local/python3/lib/python3.9/site-packages/celery/app/base.py", line 688, in _autodiscover_tasks
    return self._autodiscover_tasks_from_names(packages, related_name)
  File "/usr/local/python3/lib/python3.9/site-packages/celery/app/base.py", line 694, in _autodiscover_tasks_from_names
    packages() if callable(packages) else packages, related_name,
  File "/home/netaxe/netboost/celery.py", line 46, in <lambda>
    app.autodiscover_tasks(lambda: [n.name for n in apps.get_app_configs()])
  File "/usr/local/python3/lib/python3.9/site-packages/django/apps/registry.py", line 145, in get_app_configs
    self.check_apps_ready()
  File "/usr/local/python3/lib/python3.9/site-packages/django/apps/registry.py", line 136, in check_apps_ready
    raise AppRegistryNotReady("Apps aren't loaded yet.")
django.core.exceptions.AppRegistryNotReady: Apps aren't loaded yet.
[2022-10-11 10:26:49,296][celery.utils.dispatch.signal.send():280] [ERROR] Signal handler <bound method DjangoFixup.on_import_modules of <celery.fixups.django.DjangoFixup object at 0x7fad58c417c0>> raised: ImproperlyConfigured("Application labels aren't unique, duplicates: system")
Traceback (most recent call last):
  File "/usr/local/python3/lib/python3.9/site-packages/celery/utils/dispatch/signal.py", line 276, in send
    response = receiver(signal=self, sender=sender, **named)
  File "/usr/local/python3/lib/python3.9/site-packages/celery/fixups/django.py", line 82, in on_import_modules
    self.worker_fixup.validate_models()
  File "/usr/local/python3/lib/python3.9/site-packages/celery/fixups/django.py", line 120, in validate_models
    self.django_setup()
  File "/usr/local/python3/lib/python3.9/site-packages/celery/fixups/django.py", line 116, in django_setup
    django.setup()
  File "/usr/local/python3/lib/python3.9/site-packages/django/__init__.py", line 24, in setup
    apps.populate(settings.INSTALLED_APPS)
  File "/usr/local/python3/lib/python3.9/site-packages/django/apps/registry.py", line 93, in populate
    raise ImproperlyConfigured(
django.core.exceptions.ImproperlyConfigured: Application labels aren't unique, duplicates: system
[2022-10-11 10:26:49,297][celery.utils.dispatch.signal.send():280] [ERROR] Signal handler <promise@0x7fad58c4bf70 --> <bound method Celery._autodiscover_tasks of <Celery netboost at 0x7fad59558910>>> raised: AppRegistryNotReady("Apps aren't loaded yet.")
Traceback (most recent call last):
  File "/usr/local/python3/lib/python3.9/site-packages/celery/utils/dispatch/signal.py", line 276, in send
    response = receiver(signal=self, sender=sender, **named)
  File "/usr/local/python3/lib/python3.9/site-packages/vine/promises.py", line 160, in __call__
    return self.throw()
  File "/usr/local/python3/lib/python3.9/site-packages/vine/promises.py", line 157, in __call__
    retval = fun(*final_args, **final_kwargs)
  File "/usr/local/python3/lib/python3.9/site-packages/celery/app/base.py", line 688, in _autodiscover_tasks
    return self._autodiscover_tasks_from_names(packages, related_name)
  File "/usr/local/python3/lib/python3.9/site-packages/celery/app/base.py", line 694, in _autodiscover_tasks_from_names
    packages() if callable(packages) else packages, related_name,
  File "/home/netaxe/netboost/celery.py", line 46, in <lambda>
    app.autodiscover_tasks(lambda: [n.name for n in apps.get_app_configs()])
  File "/usr/local/python3/lib/python3.9/site-packages/django/apps/registry.py", line 145, in get_app_configs
    self.check_apps_ready()
  File "/usr/local/python3/lib/python3.9/site-packages/django/apps/registry.py", line 136, in check_apps_ready
    raise AppRegistryNotReady("Apps aren't loaded yet.")
django.core.exceptions.AppRegistryNotReady: Apps aren't loaded yet.
[2022-10-11 10:26:49,730][celery.utils.dispatch.signal.send():280] [ERROR] Signal handler <bound method DjangoFixup.on_import_modules of <celery.fixups.django.DjangoFixup object at 0x7f0b9c7e27c0>> raised: ImproperlyConfigured("Application labels aren't unique, duplicates: system")
Traceback (most recent call last):
  File "/usr/local/python3/lib/python3.9/site-packages/celery/utils/dispatch/signal.py", line 276, in send
    response = receiver(signal=self, sender=sender, **named)
  File "/usr/local/python3/lib/python3.9/site-packages/celery/fixups/django.py", line 82, in on_import_modules
    self.worker_fixup.validate_models()
  File "/usr/local/python3/lib/python3.9/site-packages/celery/fixups/django.py", line 120, in validate_models
    self.django_setup()
  File "/usr/local/python3/lib/python3.9/site-packages/celery/fixups/django.py", line 116, in django_setup
    django.setup()
  File "/usr/local/python3/lib/python3.9/site-packages/django/__init__.py", line 24, in setup
    apps.populate(settings.INSTALLED_APPS)
  File "/usr/local/python3/lib/python3.9/site-packages/django/apps/registry.py", line 93, in populate
    raise ImproperlyConfigured(
django.core.exceptions.ImproperlyConfigured: Application labels aren't unique, duplicates: system
[2022-10-11 10:26:49,732][celery.utils.dispatch.signal.send():280] [ERROR] Signal handler <promise@0x7f0b9c7ecf70 --> <bound method Celery._autodiscover_tasks of <Celery netboost at 0x7f0b9d0f9910>>> raised: AppRegistryNotReady("Apps aren't loaded yet.")
Traceback (most recent call last):
  File "/usr/local/python3/lib/python3.9/site-packages/celery/utils/dispatch/signal.py", line 276, in send
    response = receiver(signal=self, sender=sender, **named)
  File "/usr/local/python3/lib/python3.9/site-packages/vine/promises.py", line 160, in __call__
    return self.throw()
  File "/usr/local/python3/lib/python3.9/site-packages/vine/promises.py", line 157, in __call__
    retval = fun(*final_args, **final_kwargs)
  File "/usr/local/python3/lib/python3.9/site-packages/celery/app/base.py", line 688, in _autodiscover_tasks
    return self._autodiscover_tasks_from_names(packages, related_name)
  File "/usr/local/python3/lib/python3.9/site-packages/celery/app/base.py", line 694, in _autodiscover_tasks_from_names
    packages() if callable(packages) else packages, related_name,
  File "/home/netaxe/netboost/celery.py", line 46, in <lambda>
    app.autodiscover_tasks(lambda: [n.name for n in apps.get_app_configs()])
  File "/usr/local/python3/lib/python3.9/site-packages/django/apps/registry.py", line 145, in get_app_configs
    self.check_apps_ready()
  File "/usr/local/python3/lib/python3.9/site-packages/django/apps/registry.py", line 136, in check_apps_ready
    raise AppRegistryNotReady("Apps aren't loaded yet.")
django.core.exceptions.AppRegistryNotReady: Apps aren't loaded yet.
[2022-10-11 10:26:52,608][celery.utils.dispatch.signal.send():280] [ERROR] Signal handler <bound method DjangoFixup.on_import_modules of <celery.fixups.django.DjangoFixup object at 0x7f752ff26760>> raised: ImproperlyConfigured("Application labels aren't unique, duplicates: system")
Traceback (most recent call last):
  File "/usr/local/python3/lib/python3.9/site-packages/celery/utils/dispatch/signal.py", line 276, in send
    response = receiver(signal=self, sender=sender, **named)
  File "/usr/local/python3/lib/python3.9/site-packages/celery/fixups/django.py", line 82, in on_import_modules
    self.worker_fixup.validate_models()
  File "/usr/local/python3/lib/python3.9/site-packages/celery/fixups/django.py", line 120, in validate_models
    self.django_setup()
  File "/usr/local/python3/lib/python3.9/site-packages/celery/fixups/django.py", line 116, in django_setup
    django.setup()
  File "/usr/local/python3/lib/python3.9/site-packages/django/__init__.py", line 24, in setup
    apps.populate(settings.INSTALLED_APPS)
  File "/usr/local/python3/lib/python3.9/site-packages/django/apps/registry.py", line 93, in populate
    raise ImproperlyConfigured(
django.core.exceptions.ImproperlyConfigured: Application labels aren't unique, duplicates: system
[2022-10-11 10:26:52,609][celery.utils.dispatch.signal.send():280] [ERROR] Signal handler <promise@0x7f752ff31f70 --> <bound method Celery._autodiscover_tasks of <Celery netboost at 0x7f753083e8b0>>> raised: AppRegistryNotReady("Apps aren't loaded yet.")
Traceback (most recent call last):
  File "/usr/local/python3/lib/python3.9/site-packages/celery/utils/dispatch/signal.py", line 276, in send
    response = receiver(signal=self, sender=sender, **named)
  File "/usr/local/python3/lib/python3.9/site-packages/vine/promises.py", line 160, in __call__
    return self.throw()
  File "/usr/local/python3/lib/python3.9/site-packages/vine/promises.py", line 157, in __call__
    retval = fun(*final_args, **final_kwargs)
  File "/usr/local/python3/lib/python3.9/site-packages/celery/app/base.py", line 688, in _autodiscover_tasks
    return self._autodiscover_tasks_from_names(packages, related_name)
  File "/usr/local/python3/lib/python3.9/site-packages/celery/app/base.py", line 694, in _autodiscover_tasks_from_names
    packages() if callable(packages) else packages, related_name,
  File "/home/netaxe/netboost/celery.py", line 46, in <lambda>
    app.autodiscover_tasks(lambda: [n.name for n in apps.get_app_configs()])
  File "/usr/local/python3/lib/python3.9/site-packages/django/apps/registry.py", line 145, in get_app_configs
    self.check_apps_ready()
  File "/usr/local/python3/lib/python3.9/site-packages/django/apps/registry.py", line 136, in check_apps_ready
    raise AppRegistryNotReady("Apps aren't loaded yet.")
django.core.exceptions.AppRegistryNotReady: Apps aren't loaded yet.
[2022-10-11 10:26:52,669][celery.utils.dispatch.signal.send():280] [ERROR] Signal handler <bound method DjangoFixup.on_import_modules of <celery.fixups.django.DjangoFixup object at 0x7f16aff45760>> raised: ImproperlyConfigured("Application labels aren't unique, duplicates: system")
Traceback (most recent call last):
  File "/usr/local/python3/lib/python3.9/site-packages/celery/utils/dispatch/signal.py", line 276, in send
    response = receiver(signal=self, sender=sender, **named)
  File "/usr/local/python3/lib/python3.9/site-packages/celery/fixups/django.py", line 82, in on_import_modules
    self.worker_fixup.validate_models()
  File "/usr/local/python3/lib/python3.9/site-packages/celery/fixups/django.py", line 120, in validate_models
    self.django_setup()
  File "/usr/local/python3/lib/python3.9/site-packages/celery/fixups/django.py", line 116, in django_setup
    django.setup()
  File "/usr/local/python3/lib/python3.9/site-packages/django/__init__.py", line 24, in setup
    apps.populate(settings.INSTALLED_APPS)
  File "/usr/local/python3/lib/python3.9/site-packages/django/apps/registry.py", line 93, in populate
    raise ImproperlyConfigured(
django.core.exceptions.ImproperlyConfigured: Application labels aren't unique, duplicates: system
[2022-10-11 10:26:52,670][celery.utils.dispatch.signal.send():280] [ERROR] Signal handler <promise@0x7f16aff51f70 --> <bound method Celery._autodiscover_tasks of <Celery netboost at 0x7f16b085d8b0>>> raised: AppRegistryNotReady("Apps aren't loaded yet.")
Traceback (most recent call last):
  File "/usr/local/python3/lib/python3.9/site-packages/celery/utils/dispatch/signal.py", line 276, in send
    response = receiver(signal=self, sender=sender, **named)
  File "/usr/local/python3/lib/python3.9/site-packages/vine/promises.py", line 160, in __call__
    return self.throw()
  File "/usr/local/python3/lib/python3.9/site-packages/vine/promises.py", line 157, in __call__
    retval = fun(*final_args, **final_kwargs)
  File "/usr/local/python3/lib/python3.9/site-packages/celery/app/base.py", line 688, in _autodiscover_tasks
    return self._autodiscover_tasks_from_names(packages, related_name)
  File "/usr/local/python3/lib/python3.9/site-packages/celery/app/base.py", line 694, in _autodiscover_tasks_from_names
    packages() if callable(packages) else packages, related_name,
  File "/home/netaxe/netboost/celery.py", line 46, in <lambda>
    app.autodiscover_tasks(lambda: [n.name for n in apps.get_app_configs()])
  File "/usr/local/python3/lib/python3.9/site-packages/django/apps/registry.py", line 145, in get_app_configs
    self.check_apps_ready()
  File "/usr/local/python3/lib/python3.9/site-packages/django/apps/registry.py", line 136, in check_apps_ready
    raise AppRegistryNotReady("Apps aren't loaded yet.")
django.core.exceptions.AppRegistryNotReady: Apps aren't loaded yet.
[2022-10-11 10:37:24,754][celery.utils.dispatch.signal.send():280] [ERROR] Signal handler <bound method DjangoFixup.on_import_modules of <celery.fixups.django.DjangoFixup object at 0x7f47c51ae760>> raised: ImproperlyConfigured("Application labels aren't unique, duplicates: system")
Traceback (most recent call last):
  File "/usr/local/python3/lib/python3.9/site-packages/celery/utils/dispatch/signal.py", line 276, in send
    response = receiver(signal=self, sender=sender, **named)
  File "/usr/local/python3/lib/python3.9/site-packages/celery/fixups/django.py", line 82, in on_import_modules
    self.worker_fixup.validate_models()
  File "/usr/local/python3/lib/python3.9/site-packages/celery/fixups/django.py", line 120, in validate_models
    self.django_setup()
  File "/usr/local/python3/lib/python3.9/site-packages/celery/fixups/django.py", line 116, in django_setup
    django.setup()
  File "/usr/local/python3/lib/python3.9/site-packages/django/__init__.py", line 24, in setup
    apps.populate(settings.INSTALLED_APPS)
  File "/usr/local/python3/lib/python3.9/site-packages/django/apps/registry.py", line 93, in populate
    raise ImproperlyConfigured(
django.core.exceptions.ImproperlyConfigured: Application labels aren't unique, duplicates: system
[2022-10-11 10:37:24,755][celery.utils.dispatch.signal.send():280] [ERROR] Signal handler <promise@0x7f47c51b9f70 --> <bound method Celery._autodiscover_tasks of <Celery netboost at 0x7f47c5ac68b0>>> raised: AppRegistryNotReady("Apps aren't loaded yet.")
Traceback (most recent call last):
  File "/usr/local/python3/lib/python3.9/site-packages/celery/utils/dispatch/signal.py", line 276, in send
    response = receiver(signal=self, sender=sender, **named)
  File "/usr/local/python3/lib/python3.9/site-packages/vine/promises.py", line 160, in __call__
    return self.throw()
  File "/usr/local/python3/lib/python3.9/site-packages/vine/promises.py", line 157, in __call__
    retval = fun(*final_args, **final_kwargs)
  File "/usr/local/python3/lib/python3.9/site-packages/celery/app/base.py", line 688, in _autodiscover_tasks
    return self._autodiscover_tasks_from_names(packages, related_name)
  File "/usr/local/python3/lib/python3.9/site-packages/celery/app/base.py", line 694, in _autodiscover_tasks_from_names
    packages() if callable(packages) else packages, related_name,
  File "/home/netaxe/netboost/celery.py", line 46, in <lambda>
    app.autodiscover_tasks(lambda: [n.name for n in apps.get_app_configs()])
  File "/usr/local/python3/lib/python3.9/site-packages/django/apps/registry.py", line 145, in get_app_configs
    self.check_apps_ready()
  File "/usr/local/python3/lib/python3.9/site-packages/django/apps/registry.py", line 136, in check_apps_ready
    raise AppRegistryNotReady("Apps aren't loaded yet.")
django.core.exceptions.AppRegistryNotReady: Apps aren't loaded yet.
[2022-10-11 10:37:25,026][celery.utils.dispatch.signal.send():280] [ERROR] Signal handler <bound method DjangoFixup.on_import_modules of <celery.fixups.django.DjangoFixup object at 0x7f7c2e5e9760>> raised: ImproperlyConfigured("Application labels aren't unique, duplicates: system")
Traceback (most recent call last):
  File "/usr/local/python3/lib/python3.9/site-packages/celery/utils/dispatch/signal.py", line 276, in send
    response = receiver(signal=self, sender=sender, **named)
  File "/usr/local/python3/lib/python3.9/site-packages/celery/fixups/django.py", line 82, in on_import_modules
    self.worker_fixup.validate_models()
  File "/usr/local/python3/lib/python3.9/site-packages/celery/fixups/django.py", line 120, in validate_models
    self.django_setup()
  File "/usr/local/python3/lib/python3.9/site-packages/celery/fixups/django.py", line 116, in django_setup
    django.setup()
  File "/usr/local/python3/lib/python3.9/site-packages/django/__init__.py", line 24, in setup
    apps.populate(settings.INSTALLED_APPS)
  File "/usr/local/python3/lib/python3.9/site-packages/django/apps/registry.py", line 93, in populate
    raise ImproperlyConfigured(
django.core.exceptions.ImproperlyConfigured: Application labels aren't unique, duplicates: system
[2022-10-11 10:37:25,028][celery.utils.dispatch.signal.send():280] [ERROR] Signal handler <promise@0x7f7c2e5f4f70 --> <bound method Celery._autodiscover_tasks of <Celery netboost at 0x7f7c2ef018b0>>> raised: AppRegistryNotReady("Apps aren't loaded yet.")
Traceback (most recent call last):
  File "/usr/local/python3/lib/python3.9/site-packages/celery/utils/dispatch/signal.py", line 276, in send
    response = receiver(signal=self, sender=sender, **named)
  File "/usr/local/python3/lib/python3.9/site-packages/vine/promises.py", line 160, in __call__
    return self.throw()
  File "/usr/local/python3/lib/python3.9/site-packages/vine/promises.py", line 157, in __call__
    retval = fun(*final_args, **final_kwargs)
  File "/usr/local/python3/lib/python3.9/site-packages/celery/app/base.py", line 688, in _autodiscover_tasks
    return self._autodiscover_tasks_from_names(packages, related_name)
  File "/usr/local/python3/lib/python3.9/site-packages/celery/app/base.py", line 694, in _autodiscover_tasks_from_names
    packages() if callable(packages) else packages, related_name,
  File "/home/netaxe/netboost/celery.py", line 46, in <lambda>
    app.autodiscover_tasks(lambda: [n.name for n in apps.get_app_configs()])
  File "/usr/local/python3/lib/python3.9/site-packages/django/apps/registry.py", line 145, in get_app_configs
    self.check_apps_ready()
  File "/usr/local/python3/lib/python3.9/site-packages/django/apps/registry.py", line 136, in check_apps_ready
    raise AppRegistryNotReady("Apps aren't loaded yet.")
django.core.exceptions.AppRegistryNotReady: Apps aren't loaded yet.
[2022-10-11 10:37:37,375][celery.utils.dispatch.signal.send():280] [ERROR] Signal handler <bound method DjangoFixup.on_import_modules of <celery.fixups.django.DjangoFixup object at 0x7f85e87d7760>> raised: ImproperlyConfigured("Application labels aren't unique, duplicates: system")
Traceback (most recent call last):
  File "/usr/local/python3/lib/python3.9/site-packages/celery/utils/dispatch/signal.py", line 276, in send
    response = receiver(signal=self, sender=sender, **named)
  File "/usr/local/python3/lib/python3.9/site-packages/celery/fixups/django.py", line 82, in on_import_modules
    self.worker_fixup.validate_models()
  File "/usr/local/python3/lib/python3.9/site-packages/celery/fixups/django.py", line 120, in validate_models
    self.django_setup()
  File "/usr/local/python3/lib/python3.9/site-packages/celery/fixups/django.py", line 116, in django_setup
    django.setup()
  File "/usr/local/python3/lib/python3.9/site-packages/django/__init__.py", line 24, in setup
    apps.populate(settings.INSTALLED_APPS)
  File "/usr/local/python3/lib/python3.9/site-packages/django/apps/registry.py", line 93, in populate
    raise ImproperlyConfigured(
django.core.exceptions.ImproperlyConfigured: Application labels aren't unique, duplicates: system
[2022-10-11 10:37:37,376][celery.utils.dispatch.signal.send():280] [ERROR] Signal handler <promise@0x7f85e87e3f70 --> <bound method Celery._autodiscover_tasks of <Celery netboost at 0x7f85e90ef8b0>>> raised: AppRegistryNotReady("Apps aren't loaded yet.")
Traceback (most recent call last):
  File "/usr/local/python3/lib/python3.9/site-packages/celery/utils/dispatch/signal.py", line 276, in send
    response = receiver(signal=self, sender=sender, **named)
  File "/usr/local/python3/lib/python3.9/site-packages/vine/promises.py", line 160, in __call__
    return self.throw()
  File "/usr/local/python3/lib/python3.9/site-packages/vine/promises.py", line 157, in __call__
    retval = fun(*final_args, **final_kwargs)
  File "/usr/local/python3/lib/python3.9/site-packages/celery/app/base.py", line 688, in _autodiscover_tasks
    return self._autodiscover_tasks_from_names(packages, related_name)
  File "/usr/local/python3/lib/python3.9/site-packages/celery/app/base.py", line 694, in _autodiscover_tasks_from_names
    packages() if callable(packages) else packages, related_name,
  File "/home/netaxe/netboost/celery.py", line 46, in <lambda>
    app.autodiscover_tasks(lambda: [n.name for n in apps.get_app_configs()])
  File "/usr/local/python3/lib/python3.9/site-packages/django/apps/registry.py", line 145, in get_app_configs
    self.check_apps_ready()
  File "/usr/local/python3/lib/python3.9/site-packages/django/apps/registry.py", line 136, in check_apps_ready
    raise AppRegistryNotReady("Apps aren't loaded yet.")
django.core.exceptions.AppRegistryNotReady: Apps aren't loaded yet.
[2022-10-11 10:37:37,727][celery.utils.dispatch.signal.send():280] [ERROR] Signal handler <bound method DjangoFixup.on_import_modules of <celery.fixups.django.DjangoFixup object at 0x7f2a57522760>> raised: ImproperlyConfigured("Application labels aren't unique, duplicates: system")
Traceback (most recent call last):
  File "/usr/local/python3/lib/python3.9/site-packages/celery/utils/dispatch/signal.py", line 276, in send
    response = receiver(signal=self, sender=sender, **named)
  File "/usr/local/python3/lib/python3.9/site-packages/celery/fixups/django.py", line 82, in on_import_modules
    self.worker_fixup.validate_models()
  File "/usr/local/python3/lib/python3.9/site-packages/celery/fixups/django.py", line 120, in validate_models
    self.django_setup()
  File "/usr/local/python3/lib/python3.9/site-packages/celery/fixups/django.py", line 116, in django_setup
    django.setup()
  File "/usr/local/python3/lib/python3.9/site-packages/django/__init__.py", line 24, in setup
    apps.populate(settings.INSTALLED_APPS)
  File "/usr/local/python3/lib/python3.9/site-packages/django/apps/registry.py", line 93, in populate
    raise ImproperlyConfigured(
django.core.exceptions.ImproperlyConfigured: Application labels aren't unique, duplicates: system
[2022-10-11 10:37:37,728][celery.utils.dispatch.signal.send():280] [ERROR] Signal handler <promise@0x7f2a5752df70 --> <bound method Celery._autodiscover_tasks of <Celery netboost at 0x7f2a57e3a8b0>>> raised: AppRegistryNotReady("Apps aren't loaded yet.")
Traceback (most recent call last):
  File "/usr/local/python3/lib/python3.9/site-packages/celery/utils/dispatch/signal.py", line 276, in send
    response = receiver(signal=self, sender=sender, **named)
  File "/usr/local/python3/lib/python3.9/site-packages/vine/promises.py", line 160, in __call__
    return self.throw()
  File "/usr/local/python3/lib/python3.9/site-packages/vine/promises.py", line 157, in __call__
    retval = fun(*final_args, **final_kwargs)
  File "/usr/local/python3/lib/python3.9/site-packages/celery/app/base.py", line 688, in _autodiscover_tasks
    return self._autodiscover_tasks_from_names(packages, related_name)
  File "/usr/local/python3/lib/python3.9/site-packages/celery/app/base.py", line 694, in _autodiscover_tasks_from_names
    packages() if callable(packages) else packages, related_name,
  File "/home/netaxe/netboost/celery.py", line 46, in <lambda>
    app.autodiscover_tasks(lambda: [n.name for n in apps.get_app_configs()])
  File "/usr/local/python3/lib/python3.9/site-packages/django/apps/registry.py", line 145, in get_app_configs
    self.check_apps_ready()
  File "/usr/local/python3/lib/python3.9/site-packages/django/apps/registry.py", line 136, in check_apps_ready
    raise AppRegistryNotReady("Apps aren't loaded yet.")
django.core.exceptions.AppRegistryNotReady: Apps aren't loaded yet.
[2022-10-11 11:32:30,709][celery.utils.dispatch.signal.send():280] [ERROR] Signal handler <bound method DjangoFixup.on_import_modules of <celery.fixups.django.DjangoFixup object at 0x7fb662c6b850>> raised: ImproperlyConfigured("Application labels aren't unique, duplicates: system")
Traceback (most recent call last):
  File "/usr/local/python3/lib/python3.9/site-packages/celery/utils/dispatch/signal.py", line 276, in send
    response = receiver(signal=self, sender=sender, **named)
  File "/usr/local/python3/lib/python3.9/site-packages/celery/fixups/django.py", line 82, in on_import_modules
    self.worker_fixup.validate_models()
  File "/usr/local/python3/lib/python3.9/site-packages/celery/fixups/django.py", line 120, in validate_models
    self.django_setup()
  File "/usr/local/python3/lib/python3.9/site-packages/celery/fixups/django.py", line 116, in django_setup
    django.setup()
  File "/usr/local/python3/lib/python3.9/site-packages/django/__init__.py", line 24, in setup
    apps.populate(settings.INSTALLED_APPS)
  File "/usr/local/python3/lib/python3.9/site-packages/django/apps/registry.py", line 93, in populate
    raise ImproperlyConfigured(
django.core.exceptions.ImproperlyConfigured: Application labels aren't unique, duplicates: system
[2022-10-11 11:32:30,710][celery.utils.dispatch.signal.send():280] [ERROR] Signal handler <promise@0x7fb662c76f70 --> <bound method Celery._autodiscover_tasks of <Celery netboost at 0x7fb662c3f040>>> raised: AppRegistryNotReady("Apps aren't loaded yet.")
Traceback (most recent call last):
  File "/usr/local/python3/lib/python3.9/site-packages/celery/utils/dispatch/signal.py", line 276, in send
    response = receiver(signal=self, sender=sender, **named)
  File "/usr/local/python3/lib/python3.9/site-packages/vine/promises.py", line 160, in __call__
    return self.throw()
  File "/usr/local/python3/lib/python3.9/site-packages/vine/promises.py", line 157, in __call__
    retval = fun(*final_args, **final_kwargs)
  File "/usr/local/python3/lib/python3.9/site-packages/celery/app/base.py", line 688, in _autodiscover_tasks
    return self._autodiscover_tasks_from_names(packages, related_name)
  File "/usr/local/python3/lib/python3.9/site-packages/celery/app/base.py", line 694, in _autodiscover_tasks_from_names
    packages() if callable(packages) else packages, related_name,
  File "/home/netaxe/netboost/celery.py", line 46, in <lambda>
    app.autodiscover_tasks(lambda: [n.name for n in apps.get_app_configs()], force=False)
  File "/usr/local/python3/lib/python3.9/site-packages/django/apps/registry.py", line 145, in get_app_configs
    self.check_apps_ready()
  File "/usr/local/python3/lib/python3.9/site-packages/django/apps/registry.py", line 136, in check_apps_ready
    raise AppRegistryNotReady("Apps aren't loaded yet.")
django.core.exceptions.AppRegistryNotReady: Apps aren't loaded yet.
[2022-10-11 11:32:30,752][celery.utils.dispatch.signal.send():280] [ERROR] Signal handler <bound method DjangoFixup.on_import_modules of <celery.fixups.django.DjangoFixup object at 0x7f3172b35790>> raised: ImproperlyConfigured("Application labels aren't unique, duplicates: system")
Traceback (most recent call last):
  File "/usr/local/python3/lib/python3.9/site-packages/celery/utils/dispatch/signal.py", line 276, in send
    response = receiver(signal=self, sender=sender, **named)
  File "/usr/local/python3/lib/python3.9/site-packages/celery/fixups/django.py", line 82, in on_import_modules
    self.worker_fixup.validate_models()
  File "/usr/local/python3/lib/python3.9/site-packages/celery/fixups/django.py", line 120, in validate_models
    self.django_setup()
  File "/usr/local/python3/lib/python3.9/site-packages/celery/fixups/django.py", line 116, in django_setup
    django.setup()
  File "/usr/local/python3/lib/python3.9/site-packages/django/__init__.py", line 24, in setup
    apps.populate(settings.INSTALLED_APPS)
  File "/usr/local/python3/lib/python3.9/site-packages/django/apps/registry.py", line 93, in populate
    raise ImproperlyConfigured(
django.core.exceptions.ImproperlyConfigured: Application labels aren't unique, duplicates: system
[2022-10-11 11:32:30,754][celery.utils.dispatch.signal.send():280] [ERROR] Signal handler <promise@0x7f3172b41f70 --> <bound method Celery._autodiscover_tasks of <Celery netboost at 0x7f3172ffcb80>>> raised: AppRegistryNotReady("Apps aren't loaded yet.")
Traceback (most recent call last):
  File "/usr/local/python3/lib/python3.9/site-packages/celery/utils/dispatch/signal.py", line 276, in send
    response = receiver(signal=self, sender=sender, **named)
  File "/usr/local/python3/lib/python3.9/site-packages/vine/promises.py", line 160, in __call__
    return self.throw()
  File "/usr/local/python3/lib/python3.9/site-packages/vine/promises.py", line 157, in __call__
    retval = fun(*final_args, **final_kwargs)
  File "/usr/local/python3/lib/python3.9/site-packages/celery/app/base.py", line 688, in _autodiscover_tasks
    return self._autodiscover_tasks_from_names(packages, related_name)
  File "/usr/local/python3/lib/python3.9/site-packages/celery/app/base.py", line 694, in _autodiscover_tasks_from_names
    packages() if callable(packages) else packages, related_name,
  File "/home/netaxe/netboost/celery.py", line 46, in <lambda>
    app.autodiscover_tasks(lambda: [n.name for n in apps.get_app_configs()], force=False)
  File "/usr/local/python3/lib/python3.9/site-packages/django/apps/registry.py", line 145, in get_app_configs
    self.check_apps_ready()
  File "/usr/local/python3/lib/python3.9/site-packages/django/apps/registry.py", line 136, in check_apps_ready
    raise AppRegistryNotReady("Apps aren't loaded yet.")
django.core.exceptions.AppRegistryNotReady: Apps aren't loaded yet.
[2022-10-11 11:32:43,571][celery.utils.dispatch.signal.send():280] [ERROR] Signal handler <bound method DjangoFixup.on_import_modules of <celery.fixups.django.DjangoFixup object at 0x7fee106b4790>> raised: ImproperlyConfigured("Application labels aren't unique, duplicates: system")
Traceback (most recent call last):
  File "/usr/local/python3/lib/python3.9/site-packages/celery/utils/dispatch/signal.py", line 276, in send
    response = receiver(signal=self, sender=sender, **named)
  File "/usr/local/python3/lib/python3.9/site-packages/celery/fixups/django.py", line 82, in on_import_modules
    self.worker_fixup.validate_models()
  File "/usr/local/python3/lib/python3.9/site-packages/celery/fixups/django.py", line 120, in validate_models
    self.django_setup()
  File "/usr/local/python3/lib/python3.9/site-packages/celery/fixups/django.py", line 116, in django_setup
    django.setup()
  File "/usr/local/python3/lib/python3.9/site-packages/django/__init__.py", line 24, in setup
    apps.populate(settings.INSTALLED_APPS)
  File "/usr/local/python3/lib/python3.9/site-packages/django/apps/registry.py", line 93, in populate
    raise ImproperlyConfigured(
django.core.exceptions.ImproperlyConfigured: Application labels aren't unique, duplicates: system
[2022-10-11 11:32:43,573][celery.utils.dispatch.signal.send():280] [ERROR] Signal handler <promise@0x7fee106bff70 --> <bound method Celery._autodiscover_tasks of <Celery netboost at 0x7fee10b7bb80>>> raised: AppRegistryNotReady("Apps aren't loaded yet.")
Traceback (most recent call last):
  File "/usr/local/python3/lib/python3.9/site-packages/celery/utils/dispatch/signal.py", line 276, in send
    response = receiver(signal=self, sender=sender, **named)
  File "/usr/local/python3/lib/python3.9/site-packages/vine/promises.py", line 160, in __call__
    return self.throw()
  File "/usr/local/python3/lib/python3.9/site-packages/vine/promises.py", line 157, in __call__
    retval = fun(*final_args, **final_kwargs)
  File "/usr/local/python3/lib/python3.9/site-packages/celery/app/base.py", line 688, in _autodiscover_tasks
    return self._autodiscover_tasks_from_names(packages, related_name)
  File "/usr/local/python3/lib/python3.9/site-packages/celery/app/base.py", line 694, in _autodiscover_tasks_from_names
    packages() if callable(packages) else packages, related_name,
  File "/home/netaxe/netboost/celery.py", line 46, in <lambda>
    app.autodiscover_tasks(lambda: [n.name for n in apps.get_app_configs()], force=False)
  File "/usr/local/python3/lib/python3.9/site-packages/django/apps/registry.py", line 145, in get_app_configs
    self.check_apps_ready()
  File "/usr/local/python3/lib/python3.9/site-packages/django/apps/registry.py", line 136, in check_apps_ready
    raise AppRegistryNotReady("Apps aren't loaded yet.")
django.core.exceptions.AppRegistryNotReady: Apps aren't loaded yet.
[2022-10-11 11:32:43,661][celery.utils.dispatch.signal.send():280] [ERROR] Signal handler <bound method DjangoFixup.on_import_modules of <celery.fixups.django.DjangoFixup object at 0x7f013e2f0790>> raised: ImproperlyConfigured("Application labels aren't unique, duplicates: system")
Traceback (most recent call last):
  File "/usr/local/python3/lib/python3.9/site-packages/celery/utils/dispatch/signal.py", line 276, in send
    response = receiver(signal=self, sender=sender, **named)
  File "/usr/local/python3/lib/python3.9/site-packages/celery/fixups/django.py", line 82, in on_import_modules
    self.worker_fixup.validate_models()
  File "/usr/local/python3/lib/python3.9/site-packages/celery/fixups/django.py", line 120, in validate_models
    self.django_setup()
  File "/usr/local/python3/lib/python3.9/site-packages/celery/fixups/django.py", line 116, in django_setup
    django.setup()
  File "/usr/local/python3/lib/python3.9/site-packages/django/__init__.py", line 24, in setup
    apps.populate(settings.INSTALLED_APPS)
  File "/usr/local/python3/lib/python3.9/site-packages/django/apps/registry.py", line 93, in populate
    raise ImproperlyConfigured(
django.core.exceptions.ImproperlyConfigured: Application labels aren't unique, duplicates: system
[2022-10-11 11:32:43,662][celery.utils.dispatch.signal.send():280] [ERROR] Signal handler <promise@0x7f013e2fbf70 --> <bound method Celery._autodiscover_tasks of <Celery netboost at 0x7f013e7b7b80>>> raised: AppRegistryNotReady("Apps aren't loaded yet.")
Traceback (most recent call last):
  File "/usr/local/python3/lib/python3.9/site-packages/celery/utils/dispatch/signal.py", line 276, in send
    response = receiver(signal=self, sender=sender, **named)
  File "/usr/local/python3/lib/python3.9/site-packages/vine/promises.py", line 160, in __call__
    return self.throw()
  File "/usr/local/python3/lib/python3.9/site-packages/vine/promises.py", line 157, in __call__
    retval = fun(*final_args, **final_kwargs)
  File "/usr/local/python3/lib/python3.9/site-packages/celery/app/base.py", line 688, in _autodiscover_tasks
    return self._autodiscover_tasks_from_names(packages, related_name)
  File "/usr/local/python3/lib/python3.9/site-packages/celery/app/base.py", line 694, in _autodiscover_tasks_from_names
    packages() if callable(packages) else packages, related_name,
  File "/home/netaxe/netboost/celery.py", line 46, in <lambda>
    app.autodiscover_tasks(lambda: [n.name for n in apps.get_app_configs()], force=False)
  File "/usr/local/python3/lib/python3.9/site-packages/django/apps/registry.py", line 145, in get_app_configs
    self.check_apps_ready()
  File "/usr/local/python3/lib/python3.9/site-packages/django/apps/registry.py", line 136, in check_apps_ready
    raise AppRegistryNotReady("Apps aren't loaded yet.")
django.core.exceptions.AppRegistryNotReady: Apps aren't loaded yet.
[2022-10-11 11:33:18,958][celery.utils.dispatch.signal.send():280] [ERROR] Signal handler <bound method DjangoFixup.on_import_modules of <celery.fixups.django.DjangoFixup object at 0x7ffa3f398790>> raised: ImproperlyConfigured("Application labels aren't unique, duplicates: system")
Traceback (most recent call last):
  File "/usr/local/python3/lib/python3.9/site-packages/celery/utils/dispatch/signal.py", line 276, in send
    response = receiver(signal=self, sender=sender, **named)
  File "/usr/local/python3/lib/python3.9/site-packages/celery/fixups/django.py", line 82, in on_import_modules
    self.worker_fixup.validate_models()
  File "/usr/local/python3/lib/python3.9/site-packages/celery/fixups/django.py", line 120, in validate_models
    self.django_setup()
  File "/usr/local/python3/lib/python3.9/site-packages/celery/fixups/django.py", line 116, in django_setup
    django.setup()
  File "/usr/local/python3/lib/python3.9/site-packages/django/__init__.py", line 24, in setup
    apps.populate(settings.INSTALLED_APPS)
  File "/usr/local/python3/lib/python3.9/site-packages/django/apps/registry.py", line 93, in populate
    raise ImproperlyConfigured(
django.core.exceptions.ImproperlyConfigured: Application labels aren't unique, duplicates: system
[2022-10-11 11:33:18,960][celery.utils.dispatch.signal.send():280] [ERROR] Signal handler <promise@0x7ffa3f3a3f70 --> <bound method Celery._autodiscover_tasks of <Celery netboost at 0x7ffa3f85fb80>>> raised: AppRegistryNotReady("Apps aren't loaded yet.")
Traceback (most recent call last):
  File "/usr/local/python3/lib/python3.9/site-packages/celery/utils/dispatch/signal.py", line 276, in send
    response = receiver(signal=self, sender=sender, **named)
  File "/usr/local/python3/lib/python3.9/site-packages/vine/promises.py", line 160, in __call__
    return self.throw()
  File "/usr/local/python3/lib/python3.9/site-packages/vine/promises.py", line 157, in __call__
    retval = fun(*final_args, **final_kwargs)
  File "/usr/local/python3/lib/python3.9/site-packages/celery/app/base.py", line 688, in _autodiscover_tasks
    return self._autodiscover_tasks_from_names(packages, related_name)
  File "/usr/local/python3/lib/python3.9/site-packages/celery/app/base.py", line 694, in _autodiscover_tasks_from_names
    packages() if callable(packages) else packages, related_name,
  File "/home/netaxe/netboost/celery.py", line 46, in <lambda>
    app.autodiscover_tasks(lambda: [n.name for n in apps.get_app_configs()], force=False)
  File "/usr/local/python3/lib/python3.9/site-packages/django/apps/registry.py", line 145, in get_app_configs
    self.check_apps_ready()
  File "/usr/local/python3/lib/python3.9/site-packages/django/apps/registry.py", line 136, in check_apps_ready
    raise AppRegistryNotReady("Apps aren't loaded yet.")
django.core.exceptions.AppRegistryNotReady: Apps aren't loaded yet.
[2022-10-11 11:33:18,960][celery.utils.dispatch.signal.send():280] [ERROR] Signal handler <bound method DjangoFixup.on_import_modules of <celery.fixups.django.DjangoFixup object at 0x7fac8b174790>> raised: ImproperlyConfigured("Application labels aren't unique, duplicates: system")
Traceback (most recent call last):
  File "/usr/local/python3/lib/python3.9/site-packages/celery/utils/dispatch/signal.py", line 276, in send
    response = receiver(signal=self, sender=sender, **named)
  File "/usr/local/python3/lib/python3.9/site-packages/celery/fixups/django.py", line 82, in on_import_modules
    self.worker_fixup.validate_models()
  File "/usr/local/python3/lib/python3.9/site-packages/celery/fixups/django.py", line 120, in validate_models
    self.django_setup()
  File "/usr/local/python3/lib/python3.9/site-packages/celery/fixups/django.py", line 116, in django_setup
    django.setup()
  File "/usr/local/python3/lib/python3.9/site-packages/django/__init__.py", line 24, in setup
    apps.populate(settings.INSTALLED_APPS)
  File "/usr/local/python3/lib/python3.9/site-packages/django/apps/registry.py", line 93, in populate
    raise ImproperlyConfigured(
django.core.exceptions.ImproperlyConfigured: Application labels aren't unique, duplicates: system
[2022-10-11 11:33:18,961][celery.utils.dispatch.signal.send():280] [ERROR] Signal handler <promise@0x7fac8b17ff70 --> <bound method Celery._autodiscover_tasks of <Celery netboost at 0x7fac8b63bb80>>> raised: AppRegistryNotReady("Apps aren't loaded yet.")
Traceback (most recent call last):
  File "/usr/local/python3/lib/python3.9/site-packages/celery/utils/dispatch/signal.py", line 276, in send
    response = receiver(signal=self, sender=sender, **named)
  File "/usr/local/python3/lib/python3.9/site-packages/vine/promises.py", line 160, in __call__
    return self.throw()
  File "/usr/local/python3/lib/python3.9/site-packages/vine/promises.py", line 157, in __call__
    retval = fun(*final_args, **final_kwargs)
  File "/usr/local/python3/lib/python3.9/site-packages/celery/app/base.py", line 688, in _autodiscover_tasks
    return self._autodiscover_tasks_from_names(packages, related_name)
  File "/usr/local/python3/lib/python3.9/site-packages/celery/app/base.py", line 694, in _autodiscover_tasks_from_names
    packages() if callable(packages) else packages, related_name,
  File "/home/netaxe/netboost/celery.py", line 46, in <lambda>
    app.autodiscover_tasks(lambda: [n.name for n in apps.get_app_configs()], force=False)
  File "/usr/local/python3/lib/python3.9/site-packages/django/apps/registry.py", line 145, in get_app_configs
    self.check_apps_ready()
  File "/usr/local/python3/lib/python3.9/site-packages/django/apps/registry.py", line 136, in check_apps_ready
    raise AppRegistryNotReady("Apps aren't loaded yet.")
django.core.exceptions.AppRegistryNotReady: Apps aren't loaded yet.
[2022-10-11 15:05:23,864][celery.utils.dispatch.signal.send():280] [ERROR] Signal handler <bound method DjangoFixup.on_import_modules of <celery.fixups.django.DjangoFixup object at 0x7fbd6515b7c0>> raised: ImproperlyConfigured("Application labels aren't unique, duplicates: system")
Traceback (most recent call last):
  File "/usr/local/python3/lib/python3.9/site-packages/celery/utils/dispatch/signal.py", line 276, in send
    response = receiver(signal=self, sender=sender, **named)
  File "/usr/local/python3/lib/python3.9/site-packages/celery/fixups/django.py", line 82, in on_import_modules
    self.worker_fixup.validate_models()
  File "/usr/local/python3/lib/python3.9/site-packages/celery/fixups/django.py", line 120, in validate_models
    self.django_setup()
  File "/usr/local/python3/lib/python3.9/site-packages/celery/fixups/django.py", line 116, in django_setup
    django.setup()
  File "/usr/local/python3/lib/python3.9/site-packages/django/__init__.py", line 24, in setup
    apps.populate(settings.INSTALLED_APPS)
  File "/usr/local/python3/lib/python3.9/site-packages/django/apps/registry.py", line 93, in populate
    raise ImproperlyConfigured(
django.core.exceptions.ImproperlyConfigured: Application labels aren't unique, duplicates: system
[2022-10-11 15:05:23,866][celery.utils.dispatch.signal.send():280] [ERROR] Signal handler <promise@0x7fbd65167f70 --> <bound method Celery._autodiscover_tasks of <Celery netboost at 0x7fbd65130040>>> raised: AppRegistryNotReady("Apps aren't loaded yet.")
Traceback (most recent call last):
  File "/usr/local/python3/lib/python3.9/site-packages/celery/utils/dispatch/signal.py", line 276, in send
    response = receiver(signal=self, sender=sender, **named)
  File "/usr/local/python3/lib/python3.9/site-packages/vine/promises.py", line 160, in __call__
    return self.throw()
  File "/usr/local/python3/lib/python3.9/site-packages/vine/promises.py", line 157, in __call__
    retval = fun(*final_args, **final_kwargs)
  File "/usr/local/python3/lib/python3.9/site-packages/celery/app/base.py", line 688, in _autodiscover_tasks
    return self._autodiscover_tasks_from_names(packages, related_name)
  File "/usr/local/python3/lib/python3.9/site-packages/celery/app/base.py", line 694, in _autodiscover_tasks_from_names
    packages() if callable(packages) else packages, related_name,
  File "/home/netaxe/netboost/celery.py", line 43, in <lambda>
    app.autodiscover_tasks(lambda: [n.name for n in apps.get_app_configs()])
  File "/usr/local/python3/lib/python3.9/site-packages/django/apps/registry.py", line 145, in get_app_configs
    self.check_apps_ready()
  File "/usr/local/python3/lib/python3.9/site-packages/django/apps/registry.py", line 136, in check_apps_ready
    raise AppRegistryNotReady("Apps aren't loaded yet.")
django.core.exceptions.AppRegistryNotReady: Apps aren't loaded yet.
[2022-10-11 15:05:24,003][celery.utils.dispatch.signal.send():280] [ERROR] Signal handler <bound method DjangoFixup.on_import_modules of <celery.fixups.django.DjangoFixup object at 0x7f885b9a1760>> raised: ImproperlyConfigured("Application labels aren't unique, duplicates: system")
Traceback (most recent call last):
  File "/usr/local/python3/lib/python3.9/site-packages/celery/utils/dispatch/signal.py", line 276, in send
    response = receiver(signal=self, sender=sender, **named)
  File "/usr/local/python3/lib/python3.9/site-packages/celery/fixups/django.py", line 82, in on_import_modules
    self.worker_fixup.validate_models()
  File "/usr/local/python3/lib/python3.9/site-packages/celery/fixups/django.py", line 120, in validate_models
    self.django_setup()
  File "/usr/local/python3/lib/python3.9/site-packages/celery/fixups/django.py", line 116, in django_setup
    django.setup()
  File "/usr/local/python3/lib/python3.9/site-packages/django/__init__.py", line 24, in setup
    apps.populate(settings.INSTALLED_APPS)
  File "/usr/local/python3/lib/python3.9/site-packages/django/apps/registry.py", line 93, in populate
    raise ImproperlyConfigured(
django.core.exceptions.ImproperlyConfigured: Application labels aren't unique, duplicates: system
[2022-10-11 15:05:24,005][celery.utils.dispatch.signal.send():280] [ERROR] Signal handler <promise@0x7f885b9acf70 --> <bound method Celery._autodiscover_tasks of <Celery netboost at 0x7f885c2b98b0>>> raised: AppRegistryNotReady("Apps aren't loaded yet.")
Traceback (most recent call last):
  File "/usr/local/python3/lib/python3.9/site-packages/celery/utils/dispatch/signal.py", line 276, in send
    response = receiver(signal=self, sender=sender, **named)
  File "/usr/local/python3/lib/python3.9/site-packages/vine/promises.py", line 160, in __call__
    return self.throw()
  File "/usr/local/python3/lib/python3.9/site-packages/vine/promises.py", line 157, in __call__
    retval = fun(*final_args, **final_kwargs)
  File "/usr/local/python3/lib/python3.9/site-packages/celery/app/base.py", line 688, in _autodiscover_tasks
    return self._autodiscover_tasks_from_names(packages, related_name)
  File "/usr/local/python3/lib/python3.9/site-packages/celery/app/base.py", line 694, in _autodiscover_tasks_from_names
    packages() if callable(packages) else packages, related_name,
  File "/home/netaxe/netboost/celery.py", line 43, in <lambda>
    app.autodiscover_tasks(lambda: [n.name for n in apps.get_app_configs()])
  File "/usr/local/python3/lib/python3.9/site-packages/django/apps/registry.py", line 145, in get_app_configs
    self.check_apps_ready()
  File "/usr/local/python3/lib/python3.9/site-packages/django/apps/registry.py", line 136, in check_apps_ready
    raise AppRegistryNotReady("Apps aren't loaded yet.")
django.core.exceptions.AppRegistryNotReady: Apps aren't loaded yet.
[2022-10-11 15:07:22,588][celery.utils.dispatch.signal.send():280] [ERROR] Signal handler <bound method DjangoFixup.on_import_modules of <celery.fixups.django.DjangoFixup object at 0x7f39105eb760>> raised: ImproperlyConfigured("Application labels aren't unique, duplicates: system")
Traceback (most recent call last):
  File "/usr/local/python3/lib/python3.9/site-packages/celery/utils/dispatch/signal.py", line 276, in send
    response = receiver(signal=self, sender=sender, **named)
  File "/usr/local/python3/lib/python3.9/site-packages/celery/fixups/django.py", line 82, in on_import_modules
    self.worker_fixup.validate_models()
  File "/usr/local/python3/lib/python3.9/site-packages/celery/fixups/django.py", line 120, in validate_models
    self.django_setup()
  File "/usr/local/python3/lib/python3.9/site-packages/celery/fixups/django.py", line 116, in django_setup
    django.setup()
  File "/usr/local/python3/lib/python3.9/site-packages/django/__init__.py", line 24, in setup
    apps.populate(settings.INSTALLED_APPS)
  File "/usr/local/python3/lib/python3.9/site-packages/django/apps/registry.py", line 93, in populate
    raise ImproperlyConfigured(
django.core.exceptions.ImproperlyConfigured: Application labels aren't unique, duplicates: system
[2022-10-11 15:07:22,589][celery.utils.dispatch.signal.send():280] [ERROR] Signal handler <promise@0x7f39105f7f70 --> <bound method Celery._autodiscover_tasks of <Celery netboost at 0x7f3910f038b0>>> raised: AppRegistryNotReady("Apps aren't loaded yet.")
Traceback (most recent call last):
  File "/usr/local/python3/lib/python3.9/site-packages/celery/utils/dispatch/signal.py", line 276, in send
    response = receiver(signal=self, sender=sender, **named)
  File "/usr/local/python3/lib/python3.9/site-packages/vine/promises.py", line 160, in __call__
    return self.throw()
  File "/usr/local/python3/lib/python3.9/site-packages/vine/promises.py", line 157, in __call__
    retval = fun(*final_args, **final_kwargs)
  File "/usr/local/python3/lib/python3.9/site-packages/celery/app/base.py", line 688, in _autodiscover_tasks
    return self._autodiscover_tasks_from_names(packages, related_name)
  File "/usr/local/python3/lib/python3.9/site-packages/celery/app/base.py", line 694, in _autodiscover_tasks_from_names
    packages() if callable(packages) else packages, related_name,
  File "/home/netaxe/netboost/celery.py", line 43, in <lambda>
    app.autodiscover_tasks(lambda: [n.name for n in apps.get_app_configs()])
  File "/usr/local/python3/lib/python3.9/site-packages/django/apps/registry.py", line 145, in get_app_configs
    self.check_apps_ready()
  File "/usr/local/python3/lib/python3.9/site-packages/django/apps/registry.py", line 136, in check_apps_ready
    raise AppRegistryNotReady("Apps aren't loaded yet.")
django.core.exceptions.AppRegistryNotReady: Apps aren't loaded yet.
[2022-10-11 15:07:22,623][celery.utils.dispatch.signal.send():280] [ERROR] Signal handler <bound method DjangoFixup.on_import_modules of <celery.fixups.django.DjangoFixup object at 0x7f407f54e790>> raised: ImproperlyConfigured("Application labels aren't unique, duplicates: system")
Traceback (most recent call last):
  File "/usr/local/python3/lib/python3.9/site-packages/celery/utils/dispatch/signal.py", line 276, in send
    response = receiver(signal=self, sender=sender, **named)
  File "/usr/local/python3/lib/python3.9/site-packages/celery/fixups/django.py", line 82, in on_import_modules
    self.worker_fixup.validate_models()
  File "/usr/local/python3/lib/python3.9/site-packages/celery/fixups/django.py", line 120, in validate_models
    self.django_setup()
  File "/usr/local/python3/lib/python3.9/site-packages/celery/fixups/django.py", line 116, in django_setup
    django.setup()
  File "/usr/local/python3/lib/python3.9/site-packages/django/__init__.py", line 24, in setup
    apps.populate(settings.INSTALLED_APPS)
  File "/usr/local/python3/lib/python3.9/site-packages/django/apps/registry.py", line 93, in populate
    raise ImproperlyConfigured(
django.core.exceptions.ImproperlyConfigured: Application labels aren't unique, duplicates: system
[2022-10-11 15:07:22,624][celery.utils.dispatch.signal.send():280] [ERROR] Signal handler <promise@0x7f407f559f70 --> <bound method Celery._autodiscover_tasks of <Celery netboost at 0x7f407fe668e0>>> raised: AppRegistryNotReady("Apps aren't loaded yet.")
Traceback (most recent call last):
  File "/usr/local/python3/lib/python3.9/site-packages/celery/utils/dispatch/signal.py", line 276, in send
    response = receiver(signal=self, sender=sender, **named)
  File "/usr/local/python3/lib/python3.9/site-packages/vine/promises.py", line 160, in __call__
    return self.throw()
  File "/usr/local/python3/lib/python3.9/site-packages/vine/promises.py", line 157, in __call__
    retval = fun(*final_args, **final_kwargs)
  File "/usr/local/python3/lib/python3.9/site-packages/celery/app/base.py", line 688, in _autodiscover_tasks
    return self._autodiscover_tasks_from_names(packages, related_name)
  File "/usr/local/python3/lib/python3.9/site-packages/celery/app/base.py", line 694, in _autodiscover_tasks_from_names
    packages() if callable(packages) else packages, related_name,
  File "/home/netaxe/netboost/celery.py", line 43, in <lambda>
    app.autodiscover_tasks(lambda: [n.name for n in apps.get_app_configs()])
  File "/usr/local/python3/lib/python3.9/site-packages/django/apps/registry.py", line 145, in get_app_configs
    self.check_apps_ready()
  File "/usr/local/python3/lib/python3.9/site-packages/django/apps/registry.py", line 136, in check_apps_ready
    raise AppRegistryNotReady("Apps aren't loaded yet.")
django.core.exceptions.AppRegistryNotReady: Apps aren't loaded yet.
[2022-10-11 15:14:11,792][celery.utils.dispatch.signal.send():280] [ERROR] Signal handler <bound method DjangoFixup.on_import_modules of <celery.fixups.django.DjangoFixup object at 0x7f4e493e8760>> raised: ImproperlyConfigured("Application labels aren't unique, duplicates: system")
Traceback (most recent call last):
  File "/usr/local/python3/lib/python3.9/site-packages/celery/utils/dispatch/signal.py", line 276, in send
    response = receiver(signal=self, sender=sender, **named)
  File "/usr/local/python3/lib/python3.9/site-packages/celery/fixups/django.py", line 82, in on_import_modules
    self.worker_fixup.validate_models()
  File "/usr/local/python3/lib/python3.9/site-packages/celery/fixups/django.py", line 120, in validate_models
    self.django_setup()
  File "/usr/local/python3/lib/python3.9/site-packages/celery/fixups/django.py", line 116, in django_setup
    django.setup()
  File "/usr/local/python3/lib/python3.9/site-packages/django/__init__.py", line 24, in setup
    apps.populate(settings.INSTALLED_APPS)
  File "/usr/local/python3/lib/python3.9/site-packages/django/apps/registry.py", line 93, in populate
    raise ImproperlyConfigured(
django.core.exceptions.ImproperlyConfigured: Application labels aren't unique, duplicates: system
[2022-10-11 15:14:11,793][celery.utils.dispatch.signal.send():280] [ERROR] Signal handler <promise@0x7f4e493f3f70 --> <bound method Celery._autodiscover_tasks of <Celery netboost at 0x7f4e49d008b0>>> raised: AppRegistryNotReady("Apps aren't loaded yet.")
Traceback (most recent call last):
  File "/usr/local/python3/lib/python3.9/site-packages/celery/utils/dispatch/signal.py", line 276, in send
    response = receiver(signal=self, sender=sender, **named)
  File "/usr/local/python3/lib/python3.9/site-packages/vine/promises.py", line 160, in __call__
    return self.throw()
  File "/usr/local/python3/lib/python3.9/site-packages/vine/promises.py", line 157, in __call__
    retval = fun(*final_args, **final_kwargs)
  File "/usr/local/python3/lib/python3.9/site-packages/celery/app/base.py", line 688, in _autodiscover_tasks
    return self._autodiscover_tasks_from_names(packages, related_name)
  File "/usr/local/python3/lib/python3.9/site-packages/celery/app/base.py", line 694, in _autodiscover_tasks_from_names
    packages() if callable(packages) else packages, related_name,
  File "/home/netaxe/netboost/celery.py", line 43, in <lambda>
    app.autodiscover_tasks(lambda: [n.name for n in apps.get_app_configs()])
  File "/usr/local/python3/lib/python3.9/site-packages/django/apps/registry.py", line 145, in get_app_configs
    self.check_apps_ready()
  File "/usr/local/python3/lib/python3.9/site-packages/django/apps/registry.py", line 136, in check_apps_ready
    raise AppRegistryNotReady("Apps aren't loaded yet.")
django.core.exceptions.AppRegistryNotReady: Apps aren't loaded yet.
[2022-10-11 15:14:13,027][celery.utils.dispatch.signal.send():280] [ERROR] Signal handler <bound method DjangoFixup.on_import_modules of <celery.fixups.django.DjangoFixup object at 0x7fd5ec9aa760>> raised: ImproperlyConfigured("Application labels aren't unique, duplicates: system")
Traceback (most recent call last):
  File "/usr/local/python3/lib/python3.9/site-packages/celery/utils/dispatch/signal.py", line 276, in send
    response = receiver(signal=self, sender=sender, **named)
  File "/usr/local/python3/lib/python3.9/site-packages/celery/fixups/django.py", line 82, in on_import_modules
    self.worker_fixup.validate_models()
  File "/usr/local/python3/lib/python3.9/site-packages/celery/fixups/django.py", line 120, in validate_models
    self.django_setup()
  File "/usr/local/python3/lib/python3.9/site-packages/celery/fixups/django.py", line 116, in django_setup
    django.setup()
  File "/usr/local/python3/lib/python3.9/site-packages/django/__init__.py", line 24, in setup
    apps.populate(settings.INSTALLED_APPS)
  File "/usr/local/python3/lib/python3.9/site-packages/django/apps/registry.py", line 93, in populate
    raise ImproperlyConfigured(
django.core.exceptions.ImproperlyConfigured: Application labels aren't unique, duplicates: system
[2022-10-11 15:14:13,028][celery.utils.dispatch.signal.send():280] [ERROR] Signal handler <promise@0x7fd5ec9b5f70 --> <bound method Celery._autodiscover_tasks of <Celery netboost at 0x7fd5ed2c28b0>>> raised: AppRegistryNotReady("Apps aren't loaded yet.")
Traceback (most recent call last):
  File "/usr/local/python3/lib/python3.9/site-packages/celery/utils/dispatch/signal.py", line 276, in send
    response = receiver(signal=self, sender=sender, **named)
  File "/usr/local/python3/lib/python3.9/site-packages/vine/promises.py", line 160, in __call__
    return self.throw()
  File "/usr/local/python3/lib/python3.9/site-packages/vine/promises.py", line 157, in __call__
    retval = fun(*final_args, **final_kwargs)
  File "/usr/local/python3/lib/python3.9/site-packages/celery/app/base.py", line 688, in _autodiscover_tasks
    return self._autodiscover_tasks_from_names(packages, related_name)
  File "/usr/local/python3/lib/python3.9/site-packages/celery/app/base.py", line 694, in _autodiscover_tasks_from_names
    packages() if callable(packages) else packages, related_name,
  File "/home/netaxe/netboost/celery.py", line 43, in <lambda>
    app.autodiscover_tasks(lambda: [n.name for n in apps.get_app_configs()])
  File "/usr/local/python3/lib/python3.9/site-packages/django/apps/registry.py", line 145, in get_app_configs
    self.check_apps_ready()
  File "/usr/local/python3/lib/python3.9/site-packages/django/apps/registry.py", line 136, in check_apps_ready
    raise AppRegistryNotReady("Apps aren't loaded yet.")
django.core.exceptions.AppRegistryNotReady: Apps aren't loaded yet.
[2022-10-11 15:14:24,536][celery.utils.dispatch.signal.send():280] [ERROR] Signal handler <bound method DjangoFixup.on_import_modules of <celery.fixups.django.DjangoFixup object at 0x7fd1e6c04730>> raised: ImproperlyConfigured("Application labels aren't unique, duplicates: system")
Traceback (most recent call last):
  File "/usr/local/python3/lib/python3.9/site-packages/celery/utils/dispatch/signal.py", line 276, in send
    response = receiver(signal=self, sender=sender, **named)
  File "/usr/local/python3/lib/python3.9/site-packages/celery/fixups/django.py", line 82, in on_import_modules
    self.worker_fixup.validate_models()
  File "/usr/local/python3/lib/python3.9/site-packages/celery/fixups/django.py", line 120, in validate_models
    self.django_setup()
  File "/usr/local/python3/lib/python3.9/site-packages/celery/fixups/django.py", line 116, in django_setup
    django.setup()
  File "/usr/local/python3/lib/python3.9/site-packages/django/__init__.py", line 24, in setup
    apps.populate(settings.INSTALLED_APPS)
  File "/usr/local/python3/lib/python3.9/site-packages/django/apps/registry.py", line 93, in populate
    raise ImproperlyConfigured(
django.core.exceptions.ImproperlyConfigured: Application labels aren't unique, duplicates: system
[2022-10-11 15:14:24,537][celery.utils.dispatch.signal.send():280] [ERROR] Signal handler <promise@0x7fd1e6c0ff70 --> <bound method Celery._autodiscover_tasks of <Celery netboost at 0x7fd1e751c880>>> raised: AppRegistryNotReady("Apps aren't loaded yet.")
Traceback (most recent call last):
  File "/usr/local/python3/lib/python3.9/site-packages/celery/utils/dispatch/signal.py", line 276, in send
    response = receiver(signal=self, sender=sender, **named)
  File "/usr/local/python3/lib/python3.9/site-packages/vine/promises.py", line 160, in __call__
    return self.throw()
  File "/usr/local/python3/lib/python3.9/site-packages/vine/promises.py", line 157, in __call__
    retval = fun(*final_args, **final_kwargs)
  File "/usr/local/python3/lib/python3.9/site-packages/celery/app/base.py", line 688, in _autodiscover_tasks
    return self._autodiscover_tasks_from_names(packages, related_name)
  File "/usr/local/python3/lib/python3.9/site-packages/celery/app/base.py", line 694, in _autodiscover_tasks_from_names
    packages() if callable(packages) else packages, related_name,
  File "/home/netaxe/netboost/celery.py", line 43, in <lambda>
    app.autodiscover_tasks(lambda: [n.name for n in apps.get_app_configs()])
  File "/usr/local/python3/lib/python3.9/site-packages/django/apps/registry.py", line 145, in get_app_configs
    self.check_apps_ready()
  File "/usr/local/python3/lib/python3.9/site-packages/django/apps/registry.py", line 136, in check_apps_ready
    raise AppRegistryNotReady("Apps aren't loaded yet.")
django.core.exceptions.AppRegistryNotReady: Apps aren't loaded yet.
[2022-10-11 15:14:25,702][celery.utils.dispatch.signal.send():280] [ERROR] Signal handler <bound method DjangoFixup.on_import_modules of <celery.fixups.django.DjangoFixup object at 0x7f0411a45790>> raised: ImproperlyConfigured("Application labels aren't unique, duplicates: system")
Traceback (most recent call last):
  File "/usr/local/python3/lib/python3.9/site-packages/celery/utils/dispatch/signal.py", line 276, in send
    response = receiver(signal=self, sender=sender, **named)
  File "/usr/local/python3/lib/python3.9/site-packages/celery/fixups/django.py", line 82, in on_import_modules
    self.worker_fixup.validate_models()
  File "/usr/local/python3/lib/python3.9/site-packages/celery/fixups/django.py", line 120, in validate_models
    self.django_setup()
  File "/usr/local/python3/lib/python3.9/site-packages/celery/fixups/django.py", line 116, in django_setup
    django.setup()
  File "/usr/local/python3/lib/python3.9/site-packages/django/__init__.py", line 24, in setup
    apps.populate(settings.INSTALLED_APPS)
  File "/usr/local/python3/lib/python3.9/site-packages/django/apps/registry.py", line 93, in populate
    raise ImproperlyConfigured(
django.core.exceptions.ImproperlyConfigured: Application labels aren't unique, duplicates: system
[2022-10-11 15:14:25,703][celery.utils.dispatch.signal.send():280] [ERROR] Signal handler <promise@0x7f0411a50f70 --> <bound method Celery._autodiscover_tasks of <Celery netboost at 0x7f041235d8e0>>> raised: AppRegistryNotReady("Apps aren't loaded yet.")
Traceback (most recent call last):
  File "/usr/local/python3/lib/python3.9/site-packages/celery/utils/dispatch/signal.py", line 276, in send
    response = receiver(signal=self, sender=sender, **named)
  File "/usr/local/python3/lib/python3.9/site-packages/vine/promises.py", line 160, in __call__
    return self.throw()
  File "/usr/local/python3/lib/python3.9/site-packages/vine/promises.py", line 157, in __call__
    retval = fun(*final_args, **final_kwargs)
  File "/usr/local/python3/lib/python3.9/site-packages/celery/app/base.py", line 688, in _autodiscover_tasks
    return self._autodiscover_tasks_from_names(packages, related_name)
  File "/usr/local/python3/lib/python3.9/site-packages/celery/app/base.py", line 694, in _autodiscover_tasks_from_names
    packages() if callable(packages) else packages, related_name,
  File "/home/netaxe/netboost/celery.py", line 43, in <lambda>
    app.autodiscover_tasks(lambda: [n.name for n in apps.get_app_configs()])
  File "/usr/local/python3/lib/python3.9/site-packages/django/apps/registry.py", line 145, in get_app_configs
    self.check_apps_ready()
  File "/usr/local/python3/lib/python3.9/site-packages/django/apps/registry.py", line 136, in check_apps_ready
    raise AppRegistryNotReady("Apps aren't loaded yet.")
django.core.exceptions.AppRegistryNotReady: Apps aren't loaded yet.
[2022-10-11 15:17:43,442][celery.utils.dispatch.signal.send():280] [ERROR] Signal handler <bound method DjangoFixup.on_import_modules of <celery.fixups.django.DjangoFixup object at 0x7f4106177760>> raised: ImproperlyConfigured("Application labels aren't unique, duplicates: system")
Traceback (most recent call last):
  File "/usr/local/python3/lib/python3.9/site-packages/celery/utils/dispatch/signal.py", line 276, in send
    response = receiver(signal=self, sender=sender, **named)
  File "/usr/local/python3/lib/python3.9/site-packages/celery/fixups/django.py", line 82, in on_import_modules
    self.worker_fixup.validate_models()
  File "/usr/local/python3/lib/python3.9/site-packages/celery/fixups/django.py", line 120, in validate_models
    self.django_setup()
  File "/usr/local/python3/lib/python3.9/site-packages/celery/fixups/django.py", line 116, in django_setup
    django.setup()
  File "/usr/local/python3/lib/python3.9/site-packages/django/__init__.py", line 24, in setup
    apps.populate(settings.INSTALLED_APPS)
  File "/usr/local/python3/lib/python3.9/site-packages/django/apps/registry.py", line 93, in populate
    raise ImproperlyConfigured(
django.core.exceptions.ImproperlyConfigured: Application labels aren't unique, duplicates: system
[2022-10-11 15:17:43,443][celery.utils.dispatch.signal.send():280] [ERROR] Signal handler <promise@0x7f4106182f70 --> <bound method Celery._autodiscover_tasks of <Celery netboost at 0x7f4106a8f8b0>>> raised: AppRegistryNotReady("Apps aren't loaded yet.")
Traceback (most recent call last):
  File "/usr/local/python3/lib/python3.9/site-packages/celery/utils/dispatch/signal.py", line 276, in send
    response = receiver(signal=self, sender=sender, **named)
  File "/usr/local/python3/lib/python3.9/site-packages/vine/promises.py", line 160, in __call__
    return self.throw()
  File "/usr/local/python3/lib/python3.9/site-packages/vine/promises.py", line 157, in __call__
    retval = fun(*final_args, **final_kwargs)
  File "/usr/local/python3/lib/python3.9/site-packages/celery/app/base.py", line 688, in _autodiscover_tasks
    return self._autodiscover_tasks_from_names(packages, related_name)
  File "/usr/local/python3/lib/python3.9/site-packages/celery/app/base.py", line 694, in _autodiscover_tasks_from_names
    packages() if callable(packages) else packages, related_name,
  File "/home/netaxe/netboost/celery.py", line 43, in <lambda>
    app.autodiscover_tasks(lambda: [n.name for n in apps.get_app_configs()])
  File "/usr/local/python3/lib/python3.9/site-packages/django/apps/registry.py", line 145, in get_app_configs
    self.check_apps_ready()
  File "/usr/local/python3/lib/python3.9/site-packages/django/apps/registry.py", line 136, in check_apps_ready
    raise AppRegistryNotReady("Apps aren't loaded yet.")
django.core.exceptions.AppRegistryNotReady: Apps aren't loaded yet.
[2022-10-11 15:17:43,446][celery.utils.dispatch.signal.send():280] [ERROR] Signal handler <bound method DjangoFixup.on_import_modules of <celery.fixups.django.DjangoFixup object at 0x7f840560c760>> raised: ImproperlyConfigured("Application labels aren't unique, duplicates: system")
Traceback (most recent call last):
  File "/usr/local/python3/lib/python3.9/site-packages/celery/utils/dispatch/signal.py", line 276, in send
    response = receiver(signal=self, sender=sender, **named)
  File "/usr/local/python3/lib/python3.9/site-packages/celery/fixups/django.py", line 82, in on_import_modules
    self.worker_fixup.validate_models()
  File "/usr/local/python3/lib/python3.9/site-packages/celery/fixups/django.py", line 120, in validate_models
    self.django_setup()
  File "/usr/local/python3/lib/python3.9/site-packages/celery/fixups/django.py", line 116, in django_setup
    django.setup()
  File "/usr/local/python3/lib/python3.9/site-packages/django/__init__.py", line 24, in setup
    apps.populate(settings.INSTALLED_APPS)
  File "/usr/local/python3/lib/python3.9/site-packages/django/apps/registry.py", line 93, in populate
    raise ImproperlyConfigured(
django.core.exceptions.ImproperlyConfigured: Application labels aren't unique, duplicates: system
[2022-10-11 15:17:43,447][celery.utils.dispatch.signal.send():280] [ERROR] Signal handler <promise@0x7f8405617f70 --> <bound method Celery._autodiscover_tasks of <Celery netboost at 0x7f8405f248b0>>> raised: AppRegistryNotReady("Apps aren't loaded yet.")
Traceback (most recent call last):
  File "/usr/local/python3/lib/python3.9/site-packages/celery/utils/dispatch/signal.py", line 276, in send
    response = receiver(signal=self, sender=sender, **named)
  File "/usr/local/python3/lib/python3.9/site-packages/vine/promises.py", line 160, in __call__
    return self.throw()
  File "/usr/local/python3/lib/python3.9/site-packages/vine/promises.py", line 157, in __call__
    retval = fun(*final_args, **final_kwargs)
  File "/usr/local/python3/lib/python3.9/site-packages/celery/app/base.py", line 688, in _autodiscover_tasks
    return self._autodiscover_tasks_from_names(packages, related_name)
  File "/usr/local/python3/lib/python3.9/site-packages/celery/app/base.py", line 694, in _autodiscover_tasks_from_names
    packages() if callable(packages) else packages, related_name,
  File "/home/netaxe/netboost/celery.py", line 43, in <lambda>
    app.autodiscover_tasks(lambda: [n.name for n in apps.get_app_configs()])
  File "/usr/local/python3/lib/python3.9/site-packages/django/apps/registry.py", line 145, in get_app_configs
    self.check_apps_ready()
  File "/usr/local/python3/lib/python3.9/site-packages/django/apps/registry.py", line 136, in check_apps_ready
    raise AppRegistryNotReady("Apps aren't loaded yet.")
django.core.exceptions.AppRegistryNotReady: Apps aren't loaded yet.
[2022-10-11 15:18:28,192][celery.utils.dispatch.signal.send():280] [ERROR] Signal handler <bound method DjangoFixup.on_import_modules of <celery.fixups.django.DjangoFixup object at 0x7f480b614760>> raised: ImproperlyConfigured("Application labels aren't unique, duplicates: system")
Traceback (most recent call last):
  File "/usr/local/python3/lib/python3.9/site-packages/celery/utils/dispatch/signal.py", line 276, in send
    response = receiver(signal=self, sender=sender, **named)
  File "/usr/local/python3/lib/python3.9/site-packages/celery/fixups/django.py", line 82, in on_import_modules
    self.worker_fixup.validate_models()
  File "/usr/local/python3/lib/python3.9/site-packages/celery/fixups/django.py", line 120, in validate_models
    self.django_setup()
  File "/usr/local/python3/lib/python3.9/site-packages/celery/fixups/django.py", line 116, in django_setup
    django.setup()
  File "/usr/local/python3/lib/python3.9/site-packages/django/__init__.py", line 24, in setup
    apps.populate(settings.INSTALLED_APPS)
  File "/usr/local/python3/lib/python3.9/site-packages/django/apps/registry.py", line 93, in populate
    raise ImproperlyConfigured(
django.core.exceptions.ImproperlyConfigured: Application labels aren't unique, duplicates: system
[2022-10-11 15:18:28,194][celery.utils.dispatch.signal.send():280] [ERROR] Signal handler <promise@0x7f480b61ff70 --> <bound method Celery._autodiscover_tasks of <Celery netboost at 0x7f480bf2c8b0>>> raised: AppRegistryNotReady("Apps aren't loaded yet.")
Traceback (most recent call last):
  File "/usr/local/python3/lib/python3.9/site-packages/celery/utils/dispatch/signal.py", line 276, in send
    response = receiver(signal=self, sender=sender, **named)
  File "/usr/local/python3/lib/python3.9/site-packages/vine/promises.py", line 160, in __call__
    return self.throw()
  File "/usr/local/python3/lib/python3.9/site-packages/vine/promises.py", line 157, in __call__
    retval = fun(*final_args, **final_kwargs)
  File "/usr/local/python3/lib/python3.9/site-packages/celery/app/base.py", line 688, in _autodiscover_tasks
    return self._autodiscover_tasks_from_names(packages, related_name)
  File "/usr/local/python3/lib/python3.9/site-packages/celery/app/base.py", line 694, in _autodiscover_tasks_from_names
    packages() if callable(packages) else packages, related_name,
  File "/home/netaxe/netboost/celery.py", line 43, in <lambda>
    app.autodiscover_tasks(lambda: [n.name for n in apps.get_app_configs()])
  File "/usr/local/python3/lib/python3.9/site-packages/django/apps/registry.py", line 145, in get_app_configs
    self.check_apps_ready()
  File "/usr/local/python3/lib/python3.9/site-packages/django/apps/registry.py", line 136, in check_apps_ready
    raise AppRegistryNotReady("Apps aren't loaded yet.")
django.core.exceptions.AppRegistryNotReady: Apps aren't loaded yet.
[2022-10-11 15:18:28,319][celery.utils.dispatch.signal.send():280] [ERROR] Signal handler <bound method DjangoFixup.on_import_modules of <celery.fixups.django.DjangoFixup object at 0x7faebc436760>> raised: ImproperlyConfigured("Application labels aren't unique, duplicates: system")
Traceback (most recent call last):
  File "/usr/local/python3/lib/python3.9/site-packages/celery/utils/dispatch/signal.py", line 276, in send
    response = receiver(signal=self, sender=sender, **named)
  File "/usr/local/python3/lib/python3.9/site-packages/celery/fixups/django.py", line 82, in on_import_modules
    self.worker_fixup.validate_models()
  File "/usr/local/python3/lib/python3.9/site-packages/celery/fixups/django.py", line 120, in validate_models
    self.django_setup()
  File "/usr/local/python3/lib/python3.9/site-packages/celery/fixups/django.py", line 116, in django_setup
    django.setup()
  File "/usr/local/python3/lib/python3.9/site-packages/django/__init__.py", line 24, in setup
    apps.populate(settings.INSTALLED_APPS)
  File "/usr/local/python3/lib/python3.9/site-packages/django/apps/registry.py", line 93, in populate
    raise ImproperlyConfigured(
django.core.exceptions.ImproperlyConfigured: Application labels aren't unique, duplicates: system
[2022-10-11 15:18:28,321][celery.utils.dispatch.signal.send():280] [ERROR] Signal handler <promise@0x7faebc441f70 --> <bound method Celery._autodiscover_tasks of <Celery netboost at 0x7faebcd4e8b0>>> raised: AppRegistryNotReady("Apps aren't loaded yet.")
Traceback (most recent call last):
  File "/usr/local/python3/lib/python3.9/site-packages/celery/utils/dispatch/signal.py", line 276, in send
    response = receiver(signal=self, sender=sender, **named)
  File "/usr/local/python3/lib/python3.9/site-packages/vine/promises.py", line 160, in __call__
    return self.throw()
  File "/usr/local/python3/lib/python3.9/site-packages/vine/promises.py", line 157, in __call__
    retval = fun(*final_args, **final_kwargs)
  File "/usr/local/python3/lib/python3.9/site-packages/celery/app/base.py", line 688, in _autodiscover_tasks
    return self._autodiscover_tasks_from_names(packages, related_name)
  File "/usr/local/python3/lib/python3.9/site-packages/celery/app/base.py", line 694, in _autodiscover_tasks_from_names
    packages() if callable(packages) else packages, related_name,
  File "/home/netaxe/netboost/celery.py", line 43, in <lambda>
    app.autodiscover_tasks(lambda: [n.name for n in apps.get_app_configs()])
  File "/usr/local/python3/lib/python3.9/site-packages/django/apps/registry.py", line 145, in get_app_configs
    self.check_apps_ready()
  File "/usr/local/python3/lib/python3.9/site-packages/django/apps/registry.py", line 136, in check_apps_ready
    raise AppRegistryNotReady("Apps aren't loaded yet.")
django.core.exceptions.AppRegistryNotReady: Apps aren't loaded yet.
[2022-10-11 15:21:47,901][celery.utils.dispatch.signal.send():280] [ERROR] Signal handler <bound method DjangoFixup.on_import_modules of <celery.fixups.django.DjangoFixup object at 0x7f4e6b51a790>> raised: ImproperlyConfigured("Application labels aren't unique, duplicates: system")
Traceback (most recent call last):
  File "/usr/local/python3/lib/python3.9/site-packages/celery/utils/dispatch/signal.py", line 276, in send
    response = receiver(signal=self, sender=sender, **named)
  File "/usr/local/python3/lib/python3.9/site-packages/celery/fixups/django.py", line 82, in on_import_modules
    self.worker_fixup.validate_models()
  File "/usr/local/python3/lib/python3.9/site-packages/celery/fixups/django.py", line 120, in validate_models
    self.django_setup()
  File "/usr/local/python3/lib/python3.9/site-packages/celery/fixups/django.py", line 116, in django_setup
    django.setup()
  File "/usr/local/python3/lib/python3.9/site-packages/django/__init__.py", line 24, in setup
    apps.populate(settings.INSTALLED_APPS)
  File "/usr/local/python3/lib/python3.9/site-packages/django/apps/registry.py", line 93, in populate
    raise ImproperlyConfigured(
django.core.exceptions.ImproperlyConfigured: Application labels aren't unique, duplicates: system
[2022-10-11 15:21:47,902][celery.utils.dispatch.signal.send():280] [ERROR] Signal handler <promise@0x7f4e6b5238b0 --> <bound method Celery._autodiscover_tasks of <Celery netboost at 0x7f4e6be398b0>>> raised: AppRegistryNotReady("Apps aren't loaded yet.")
Traceback (most recent call last):
  File "/usr/local/python3/lib/python3.9/site-packages/celery/utils/dispatch/signal.py", line 276, in send
    response = receiver(signal=self, sender=sender, **named)
  File "/usr/local/python3/lib/python3.9/site-packages/vine/promises.py", line 160, in __call__
    return self.throw()
  File "/usr/local/python3/lib/python3.9/site-packages/vine/promises.py", line 157, in __call__
    retval = fun(*final_args, **final_kwargs)
  File "/usr/local/python3/lib/python3.9/site-packages/celery/app/base.py", line 688, in _autodiscover_tasks
    return self._autodiscover_tasks_from_names(packages, related_name)
  File "/usr/local/python3/lib/python3.9/site-packages/celery/app/base.py", line 694, in _autodiscover_tasks_from_names
    packages() if callable(packages) else packages, related_name,
  File "/home/netaxe/netboost/celery.py", line 42, in <lambda>
    app.autodiscover_tasks(lambda: [n.name for n in apps.get_app_configs()])
  File "/usr/local/python3/lib/python3.9/site-packages/django/apps/registry.py", line 145, in get_app_configs
    self.check_apps_ready()
  File "/usr/local/python3/lib/python3.9/site-packages/django/apps/registry.py", line 136, in check_apps_ready
    raise AppRegistryNotReady("Apps aren't loaded yet.")
django.core.exceptions.AppRegistryNotReady: Apps aren't loaded yet.
[2022-10-11 15:21:47,974][celery.utils.dispatch.signal.send():280] [ERROR] Signal handler <bound method DjangoFixup.on_import_modules of <celery.fixups.django.DjangoFixup object at 0x7f563bfb7790>> raised: ImproperlyConfigured("Application labels aren't unique, duplicates: system")
Traceback (most recent call last):
  File "/usr/local/python3/lib/python3.9/site-packages/celery/utils/dispatch/signal.py", line 276, in send
    response = receiver(signal=self, sender=sender, **named)
  File "/usr/local/python3/lib/python3.9/site-packages/celery/fixups/django.py", line 82, in on_import_modules
    self.worker_fixup.validate_models()
  File "/usr/local/python3/lib/python3.9/site-packages/celery/fixups/django.py", line 120, in validate_models
    self.django_setup()
  File "/usr/local/python3/lib/python3.9/site-packages/celery/fixups/django.py", line 116, in django_setup
    django.setup()
  File "/usr/local/python3/lib/python3.9/site-packages/django/__init__.py", line 24, in setup
    apps.populate(settings.INSTALLED_APPS)
  File "/usr/local/python3/lib/python3.9/site-packages/django/apps/registry.py", line 93, in populate
    raise ImproperlyConfigured(
django.core.exceptions.ImproperlyConfigured: Application labels aren't unique, duplicates: system
[2022-10-11 15:21:47,975][celery.utils.dispatch.signal.send():280] [ERROR] Signal handler <promise@0x7f563bfc08b0 --> <bound method Celery._autodiscover_tasks of <Celery netboost at 0x7f563c8d68b0>>> raised: AppRegistryNotReady("Apps aren't loaded yet.")
Traceback (most recent call last):
  File "/usr/local/python3/lib/python3.9/site-packages/celery/utils/dispatch/signal.py", line 276, in send
    response = receiver(signal=self, sender=sender, **named)
  File "/usr/local/python3/lib/python3.9/site-packages/vine/promises.py", line 160, in __call__
    return self.throw()
  File "/usr/local/python3/lib/python3.9/site-packages/vine/promises.py", line 157, in __call__
    retval = fun(*final_args, **final_kwargs)
  File "/usr/local/python3/lib/python3.9/site-packages/celery/app/base.py", line 688, in _autodiscover_tasks
    return self._autodiscover_tasks_from_names(packages, related_name)
  File "/usr/local/python3/lib/python3.9/site-packages/celery/app/base.py", line 694, in _autodiscover_tasks_from_names
    packages() if callable(packages) else packages, related_name,
  File "/home/netaxe/netboost/celery.py", line 42, in <lambda>
    app.autodiscover_tasks(lambda: [n.name for n in apps.get_app_configs()])
  File "/usr/local/python3/lib/python3.9/site-packages/django/apps/registry.py", line 145, in get_app_configs
    self.check_apps_ready()
  File "/usr/local/python3/lib/python3.9/site-packages/django/apps/registry.py", line 136, in check_apps_ready
    raise AppRegistryNotReady("Apps aren't loaded yet.")
django.core.exceptions.AppRegistryNotReady: Apps aren't loaded yet.
[2022-10-11 15:41:06,410][celery.utils.dispatch.signal.send():280] [ERROR] Signal handler <bound method DjangoFixup.on_import_modules of <celery.fixups.django.DjangoFixup object at 0x7fadcaa1a760>> raised: ImproperlyConfigured("Application labels aren't unique, duplicates: system")
Traceback (most recent call last):
  File "/usr/local/python3/lib/python3.9/site-packages/celery/utils/dispatch/signal.py", line 276, in send
    response = receiver(signal=self, sender=sender, **named)
  File "/usr/local/python3/lib/python3.9/site-packages/celery/fixups/django.py", line 82, in on_import_modules
    self.worker_fixup.validate_models()
  File "/usr/local/python3/lib/python3.9/site-packages/celery/fixups/django.py", line 120, in validate_models
    self.django_setup()
  File "/usr/local/python3/lib/python3.9/site-packages/celery/fixups/django.py", line 116, in django_setup
    django.setup()
  File "/usr/local/python3/lib/python3.9/site-packages/django/__init__.py", line 24, in setup
    apps.populate(settings.INSTALLED_APPS)
  File "/usr/local/python3/lib/python3.9/site-packages/django/apps/registry.py", line 93, in populate
    raise ImproperlyConfigured(
django.core.exceptions.ImproperlyConfigured: Application labels aren't unique, duplicates: system
[2022-10-11 15:41:06,410][celery.utils.dispatch.signal.send():280] [ERROR] Signal handler <bound method DjangoFixup.on_import_modules of <celery.fixups.django.DjangoFixup object at 0x7f0cd2cb1760>> raised: ImproperlyConfigured("Application labels aren't unique, duplicates: system")
Traceback (most recent call last):
  File "/usr/local/python3/lib/python3.9/site-packages/celery/utils/dispatch/signal.py", line 276, in send
    response = receiver(signal=self, sender=sender, **named)
  File "/usr/local/python3/lib/python3.9/site-packages/celery/fixups/django.py", line 82, in on_import_modules
    self.worker_fixup.validate_models()
  File "/usr/local/python3/lib/python3.9/site-packages/celery/fixups/django.py", line 120, in validate_models
    self.django_setup()
  File "/usr/local/python3/lib/python3.9/site-packages/celery/fixups/django.py", line 116, in django_setup
    django.setup()
  File "/usr/local/python3/lib/python3.9/site-packages/django/__init__.py", line 24, in setup
    apps.populate(settings.INSTALLED_APPS)
  File "/usr/local/python3/lib/python3.9/site-packages/django/apps/registry.py", line 93, in populate
    raise ImproperlyConfigured(
django.core.exceptions.ImproperlyConfigured: Application labels aren't unique, duplicates: system
[2022-10-11 15:41:06,411][celery.utils.dispatch.signal.send():280] [ERROR] Signal handler <promise@0x7f0cd2cbcf70 --> <bound method Celery._autodiscover_tasks of <Celery netboost at 0x7f0cd35c98b0>>> raised: AppRegistryNotReady("Apps aren't loaded yet.")
Traceback (most recent call last):
  File "/usr/local/python3/lib/python3.9/site-packages/celery/utils/dispatch/signal.py", line 276, in send
    response = receiver(signal=self, sender=sender, **named)
  File "/usr/local/python3/lib/python3.9/site-packages/vine/promises.py", line 160, in __call__
    return self.throw()
  File "/usr/local/python3/lib/python3.9/site-packages/vine/promises.py", line 157, in __call__
    retval = fun(*final_args, **final_kwargs)
  File "/usr/local/python3/lib/python3.9/site-packages/celery/app/base.py", line 688, in _autodiscover_tasks
    return self._autodiscover_tasks_from_names(packages, related_name)
  File "/usr/local/python3/lib/python3.9/site-packages/celery/app/base.py", line 694, in _autodiscover_tasks_from_names
    packages() if callable(packages) else packages, related_name,
  File "/home/netaxe/netboost/celery.py", line 46, in <lambda>
    app.autodiscover_tasks(lambda: [n.name for n in apps.get_app_configs()])
  File "/usr/local/python3/lib/python3.9/site-packages/django/apps/registry.py", line 145, in get_app_configs
    self.check_apps_ready()
  File "/usr/local/python3/lib/python3.9/site-packages/django/apps/registry.py", line 136, in check_apps_ready
    raise AppRegistryNotReady("Apps aren't loaded yet.")
django.core.exceptions.AppRegistryNotReady: Apps aren't loaded yet.
[2022-10-11 15:41:06,411][celery.utils.dispatch.signal.send():280] [ERROR] Signal handler <promise@0x7fadcaa25f70 --> <bound method Celery._autodiscover_tasks of <Celery netboost at 0x7fadcb3328b0>>> raised: AppRegistryNotReady("Apps aren't loaded yet.")
Traceback (most recent call last):
  File "/usr/local/python3/lib/python3.9/site-packages/celery/utils/dispatch/signal.py", line 276, in send
    response = receiver(signal=self, sender=sender, **named)
  File "/usr/local/python3/lib/python3.9/site-packages/vine/promises.py", line 160, in __call__
    return self.throw()
  File "/usr/local/python3/lib/python3.9/site-packages/vine/promises.py", line 157, in __call__
    retval = fun(*final_args, **final_kwargs)
  File "/usr/local/python3/lib/python3.9/site-packages/celery/app/base.py", line 688, in _autodiscover_tasks
    return self._autodiscover_tasks_from_names(packages, related_name)
  File "/usr/local/python3/lib/python3.9/site-packages/celery/app/base.py", line 694, in _autodiscover_tasks_from_names
    packages() if callable(packages) else packages, related_name,
  File "/home/netaxe/netboost/celery.py", line 46, in <lambda>
    app.autodiscover_tasks(lambda: [n.name for n in apps.get_app_configs()])
  File "/usr/local/python3/lib/python3.9/site-packages/django/apps/registry.py", line 145, in get_app_configs
    self.check_apps_ready()
  File "/usr/local/python3/lib/python3.9/site-packages/django/apps/registry.py", line 136, in check_apps_ready
    raise AppRegistryNotReady("Apps aren't loaded yet.")
django.core.exceptions.AppRegistryNotReady: Apps aren't loaded yet.
[2022-10-11 15:45:31,455][celery.utils.dispatch.signal.send():280] [ERROR] Signal handler <bound method DjangoFixup.on_import_modules of <celery.fixups.django.DjangoFixup object at 0x7f8e57251790>> raised: ImproperlyConfigured("Application labels aren't unique, duplicates: system")
Traceback (most recent call last):
  File "/usr/local/python3/lib/python3.9/site-packages/celery/utils/dispatch/signal.py", line 276, in send
    response = receiver(signal=self, sender=sender, **named)
  File "/usr/local/python3/lib/python3.9/site-packages/celery/fixups/django.py", line 82, in on_import_modules
    self.worker_fixup.validate_models()
  File "/usr/local/python3/lib/python3.9/site-packages/celery/fixups/django.py", line 120, in validate_models
    self.django_setup()
  File "/usr/local/python3/lib/python3.9/site-packages/celery/fixups/django.py", line 116, in django_setup
    django.setup()
  File "/usr/local/python3/lib/python3.9/site-packages/django/__init__.py", line 24, in setup
    apps.populate(settings.INSTALLED_APPS)
  File "/usr/local/python3/lib/python3.9/site-packages/django/apps/registry.py", line 93, in populate
    raise ImproperlyConfigured(
django.core.exceptions.ImproperlyConfigured: Application labels aren't unique, duplicates: system
[2022-10-11 15:45:31,457][celery.utils.dispatch.signal.send():280] [ERROR] Signal handler <promise@0x7f8e5725cf70 --> <bound method Celery._autodiscover_tasks of <Celery netboost at 0x7f8e57b698e0>>> raised: AppRegistryNotReady("Apps aren't loaded yet.")
Traceback (most recent call last):
  File "/usr/local/python3/lib/python3.9/site-packages/celery/utils/dispatch/signal.py", line 276, in send
    response = receiver(signal=self, sender=sender, **named)
  File "/usr/local/python3/lib/python3.9/site-packages/vine/promises.py", line 160, in __call__
    return self.throw()
  File "/usr/local/python3/lib/python3.9/site-packages/vine/promises.py", line 157, in __call__
    retval = fun(*final_args, **final_kwargs)
  File "/usr/local/python3/lib/python3.9/site-packages/celery/app/base.py", line 688, in _autodiscover_tasks
    return self._autodiscover_tasks_from_names(packages, related_name)
  File "/usr/local/python3/lib/python3.9/site-packages/celery/app/base.py", line 694, in _autodiscover_tasks_from_names
    packages() if callable(packages) else packages, related_name,
  File "/home/netaxe/netboost/celery.py", line 46, in <lambda>
    app.autodiscover_tasks(lambda: [n.name for n in apps.get_app_configs()])
  File "/usr/local/python3/lib/python3.9/site-packages/django/apps/registry.py", line 145, in get_app_configs
    self.check_apps_ready()
  File "/usr/local/python3/lib/python3.9/site-packages/django/apps/registry.py", line 136, in check_apps_ready
    raise AppRegistryNotReady("Apps aren't loaded yet.")
django.core.exceptions.AppRegistryNotReady: Apps aren't loaded yet.
[2022-10-11 15:45:31,796][celery.utils.dispatch.signal.send():280] [ERROR] Signal handler <bound method DjangoFixup.on_import_modules of <celery.fixups.django.DjangoFixup object at 0x7f0725fe8730>> raised: ImproperlyConfigured("Application labels aren't unique, duplicates: system")
Traceback (most recent call last):
  File "/usr/local/python3/lib/python3.9/site-packages/celery/utils/dispatch/signal.py", line 276, in send
    response = receiver(signal=self, sender=sender, **named)
  File "/usr/local/python3/lib/python3.9/site-packages/celery/fixups/django.py", line 82, in on_import_modules
    self.worker_fixup.validate_models()
  File "/usr/local/python3/lib/python3.9/site-packages/celery/fixups/django.py", line 120, in validate_models
    self.django_setup()
  File "/usr/local/python3/lib/python3.9/site-packages/celery/fixups/django.py", line 116, in django_setup
    django.setup()
  File "/usr/local/python3/lib/python3.9/site-packages/django/__init__.py", line 24, in setup
    apps.populate(settings.INSTALLED_APPS)
  File "/usr/local/python3/lib/python3.9/site-packages/django/apps/registry.py", line 93, in populate
    raise ImproperlyConfigured(
django.core.exceptions.ImproperlyConfigured: Application labels aren't unique, duplicates: system
[2022-10-11 15:45:31,797][celery.utils.dispatch.signal.send():280] [ERROR] Signal handler <promise@0x7f0725ff4f70 --> <bound method Celery._autodiscover_tasks of <Celery netboost at 0x7f0726900880>>> raised: AppRegistryNotReady("Apps aren't loaded yet.")
Traceback (most recent call last):
  File "/usr/local/python3/lib/python3.9/site-packages/celery/utils/dispatch/signal.py", line 276, in send
    response = receiver(signal=self, sender=sender, **named)
  File "/usr/local/python3/lib/python3.9/site-packages/vine/promises.py", line 160, in __call__
    return self.throw()
  File "/usr/local/python3/lib/python3.9/site-packages/vine/promises.py", line 157, in __call__
    retval = fun(*final_args, **final_kwargs)
  File "/usr/local/python3/lib/python3.9/site-packages/celery/app/base.py", line 688, in _autodiscover_tasks
    return self._autodiscover_tasks_from_names(packages, related_name)
  File "/usr/local/python3/lib/python3.9/site-packages/celery/app/base.py", line 694, in _autodiscover_tasks_from_names
    packages() if callable(packages) else packages, related_name,
  File "/home/netaxe/netboost/celery.py", line 46, in <lambda>
    app.autodiscover_tasks(lambda: [n.name for n in apps.get_app_configs()])
  File "/usr/local/python3/lib/python3.9/site-packages/django/apps/registry.py", line 145, in get_app_configs
    self.check_apps_ready()
  File "/usr/local/python3/lib/python3.9/site-packages/django/apps/registry.py", line 136, in check_apps_ready
    raise AppRegistryNotReady("Apps aren't loaded yet.")
django.core.exceptions.AppRegistryNotReady: Apps aren't loaded yet.
[2022-10-11 16:57:04,857][root.__registerBeatThreadRun():162] [ERROR] 服务心跳维持失败！
Traceback (most recent call last):
  File "/root/miniconda2/envs/netaxe/lib/python3.9/site-packages/urllib3/connection.py", line 169, in _new_conn
    conn = connection.create_connection(
  File "/root/miniconda2/envs/netaxe/lib/python3.9/site-packages/urllib3/util/connection.py", line 96, in create_connection
    raise err
  File "/root/miniconda2/envs/netaxe/lib/python3.9/site-packages/urllib3/util/connection.py", line 86, in create_connection
    sock.connect(sa)
ConnectionRefusedError: [Errno 111] Connection refused

During handling of the above exception, another exception occurred:

Traceback (most recent call last):
  File "/root/miniconda2/envs/netaxe/lib/python3.9/site-packages/urllib3/connectionpool.py", line 699, in urlopen
    httplib_response = self._make_request(
  File "/root/miniconda2/envs/netaxe/lib/python3.9/site-packages/urllib3/connectionpool.py", line 394, in _make_request
    conn.request(method, url, **httplib_request_kw)
  File "/root/miniconda2/envs/netaxe/lib/python3.9/site-packages/urllib3/connection.py", line 234, in request
    super(HTTPConnection, self).request(method, url, body=body, headers=headers)
  File "/root/miniconda2/envs/netaxe/lib/python3.9/http/client.py", line 1285, in request
    self._send_request(method, url, body, headers, encode_chunked)
  File "/root/miniconda2/envs/netaxe/lib/python3.9/http/client.py", line 1331, in _send_request
    self.endheaders(body, encode_chunked=encode_chunked)
  File "/root/miniconda2/envs/netaxe/lib/python3.9/http/client.py", line 1280, in endheaders
    self._send_output(message_body, encode_chunked=encode_chunked)
  File "/root/miniconda2/envs/netaxe/lib/python3.9/http/client.py", line 1040, in _send_output
    self.send(msg)
  File "/root/miniconda2/envs/netaxe/lib/python3.9/http/client.py", line 980, in send
    self.connect()
  File "/root/miniconda2/envs/netaxe/lib/python3.9/site-packages/urllib3/connection.py", line 200, in connect
    conn = self._new_conn()
  File "/root/miniconda2/envs/netaxe/lib/python3.9/site-packages/urllib3/connection.py", line 181, in _new_conn
    raise NewConnectionError(
urllib3.exceptions.NewConnectionError: <urllib3.connection.HTTPConnection object at 0x7f5d74799b20>: Failed to establish a new connection: [Errno 111] Connection refused

During handling of the above exception, another exception occurred:

Traceback (most recent call last):
  File "/root/miniconda2/envs/netaxe/lib/python3.9/site-packages/requests/adapters.py", line 489, in send
    resp = conn.urlopen(
  File "/root/miniconda2/envs/netaxe/lib/python3.9/site-packages/urllib3/connectionpool.py", line 755, in urlopen
    retries = retries.increment(
  File "/root/miniconda2/envs/netaxe/lib/python3.9/site-packages/urllib3/util/retry.py", line 574, in increment
    raise MaxRetryError(_pool, url, error or ResponseError(cause))
urllib3.exceptions.MaxRetryError: HTTPConnectionPool(host='10.254.2.188', port=8848): Max retries exceeded with url: /nacos/v1/ns/instance/beat?serviceName=auth&groupName=default&namespaceId=public&beat=%7B%22ip%22%3A%20%2210.254.2.188%22%2C%20%22port%22%3A%20%228001%22%2C%20%22serviceName%22%3A%20%22auth%22%2C%20%22metadata%22%3A%20%7B%7D%2C%20%22weight%22%3A%201%7D (Caused by NewConnectionError('<urllib3.connection.HTTPConnection object at 0x7f5d74799b20>: Failed to establish a new connection: [Errno 111] Connection refused'))

During handling of the above exception, another exception occurred:

Traceback (most recent call last):
  File "/root/miniconda2/envs/netaxe/lib/python3.9/site-packages/KcangNacos/nacos.py", line 153, in __registerBeatThreadRun
    re = requests.put(beatUrl[:-1])
  File "/root/miniconda2/envs/netaxe/lib/python3.9/site-packages/requests/api.py", line 130, in put
    return request("put", url, data=data, **kwargs)
  File "/root/miniconda2/envs/netaxe/lib/python3.9/site-packages/requests/api.py", line 59, in request
    return session.request(method=method, url=url, **kwargs)
  File "/root/miniconda2/envs/netaxe/lib/python3.9/site-packages/requests/sessions.py", line 587, in request
    resp = self.send(prep, **send_kwargs)
  File "/root/miniconda2/envs/netaxe/lib/python3.9/site-packages/requests/sessions.py", line 701, in send
    r = adapter.send(request, **kwargs)
  File "/root/miniconda2/envs/netaxe/lib/python3.9/site-packages/requests/adapters.py", line 565, in send
    raise ConnectionError(e, request=request)
requests.exceptions.ConnectionError: HTTPConnectionPool(host='10.254.2.188', port=8848): Max retries exceeded with url: /nacos/v1/ns/instance/beat?serviceName=auth&groupName=default&namespaceId=public&beat=%7B%22ip%22%3A%20%2210.254.2.188%22%2C%20%22port%22%3A%20%228001%22%2C%20%22serviceName%22%3A%20%22auth%22%2C%20%22metadata%22%3A%20%7B%7D%2C%20%22weight%22%3A%201%7D (Caused by NewConnectionError('<urllib3.connection.HTTPConnection object at 0x7f5d74799b20>: Failed to establish a new connection: [Errno 111] Connection refused'))
[2022-10-11 16:58:35,571][root.__registerBeatThreadRun():162] [ERROR] 服务心跳维持失败！
Traceback (most recent call last):
  File "/root/miniconda2/envs/netaxe/lib/python3.9/site-packages/urllib3/connection.py", line 169, in _new_conn
    conn = connection.create_connection(
  File "/root/miniconda2/envs/netaxe/lib/python3.9/site-packages/urllib3/util/connection.py", line 96, in create_connection
    raise err
  File "/root/miniconda2/envs/netaxe/lib/python3.9/site-packages/urllib3/util/connection.py", line 86, in create_connection
    sock.connect(sa)
ConnectionRefusedError: [Errno 111] Connection refused

During handling of the above exception, another exception occurred:

Traceback (most recent call last):
  File "/root/miniconda2/envs/netaxe/lib/python3.9/site-packages/urllib3/connectionpool.py", line 699, in urlopen
    httplib_response = self._make_request(
  File "/root/miniconda2/envs/netaxe/lib/python3.9/site-packages/urllib3/connectionpool.py", line 394, in _make_request
    conn.request(method, url, **httplib_request_kw)
  File "/root/miniconda2/envs/netaxe/lib/python3.9/site-packages/urllib3/connection.py", line 234, in request
    super(HTTPConnection, self).request(method, url, body=body, headers=headers)
  File "/root/miniconda2/envs/netaxe/lib/python3.9/http/client.py", line 1285, in request
    self._send_request(method, url, body, headers, encode_chunked)
  File "/root/miniconda2/envs/netaxe/lib/python3.9/http/client.py", line 1331, in _send_request
    self.endheaders(body, encode_chunked=encode_chunked)
  File "/root/miniconda2/envs/netaxe/lib/python3.9/http/client.py", line 1280, in endheaders
    self._send_output(message_body, encode_chunked=encode_chunked)
  File "/root/miniconda2/envs/netaxe/lib/python3.9/http/client.py", line 1040, in _send_output
    self.send(msg)
  File "/root/miniconda2/envs/netaxe/lib/python3.9/http/client.py", line 980, in send
    self.connect()
  File "/root/miniconda2/envs/netaxe/lib/python3.9/site-packages/urllib3/connection.py", line 200, in connect
    conn = self._new_conn()
  File "/root/miniconda2/envs/netaxe/lib/python3.9/site-packages/urllib3/connection.py", line 181, in _new_conn
    raise NewConnectionError(
urllib3.exceptions.NewConnectionError: <urllib3.connection.HTTPConnection object at 0x7f9709b4e520>: Failed to establish a new connection: [Errno 111] Connection refused

During handling of the above exception, another exception occurred:

Traceback (most recent call last):
  File "/root/miniconda2/envs/netaxe/lib/python3.9/site-packages/requests/adapters.py", line 489, in send
    resp = conn.urlopen(
  File "/root/miniconda2/envs/netaxe/lib/python3.9/site-packages/urllib3/connectionpool.py", line 755, in urlopen
    retries = retries.increment(
  File "/root/miniconda2/envs/netaxe/lib/python3.9/site-packages/urllib3/util/retry.py", line 574, in increment
    raise MaxRetryError(_pool, url, error or ResponseError(cause))
urllib3.exceptions.MaxRetryError: HTTPConnectionPool(host='10.254.2.188', port=8848): Max retries exceeded with url: /nacos/v1/ns/instance/beat?serviceName=auth&groupName=default&namespaceId=public&beat=%7B%22ip%22%3A%20%2210.254.2.188%22%2C%20%22port%22%3A%20%228001%22%2C%20%22serviceName%22%3A%20%22auth%22%2C%20%22metadata%22%3A%20%7B%7D%2C%20%22weight%22%3A%201%7D (Caused by NewConnectionError('<urllib3.connection.HTTPConnection object at 0x7f9709b4e520>: Failed to establish a new connection: [Errno 111] Connection refused'))

During handling of the above exception, another exception occurred:

Traceback (most recent call last):
  File "/root/miniconda2/envs/netaxe/lib/python3.9/site-packages/KcangNacos/nacos.py", line 153, in __registerBeatThreadRun
    re = requests.put(beatUrl[:-1])
  File "/root/miniconda2/envs/netaxe/lib/python3.9/site-packages/requests/api.py", line 130, in put
    return request("put", url, data=data, **kwargs)
  File "/root/miniconda2/envs/netaxe/lib/python3.9/site-packages/requests/api.py", line 59, in request
    return session.request(method=method, url=url, **kwargs)
  File "/root/miniconda2/envs/netaxe/lib/python3.9/site-packages/requests/sessions.py", line 587, in request
    resp = self.send(prep, **send_kwargs)
  File "/root/miniconda2/envs/netaxe/lib/python3.9/site-packages/requests/sessions.py", line 701, in send
    r = adapter.send(request, **kwargs)
  File "/root/miniconda2/envs/netaxe/lib/python3.9/site-packages/requests/adapters.py", line 565, in send
    raise ConnectionError(e, request=request)
requests.exceptions.ConnectionError: HTTPConnectionPool(host='10.254.2.188', port=8848): Max retries exceeded with url: /nacos/v1/ns/instance/beat?serviceName=auth&groupName=default&namespaceId=public&beat=%7B%22ip%22%3A%20%2210.254.2.188%22%2C%20%22port%22%3A%20%228001%22%2C%20%22serviceName%22%3A%20%22auth%22%2C%20%22metadata%22%3A%20%7B%7D%2C%20%22weight%22%3A%201%7D (Caused by NewConnectionError('<urllib3.connection.HTTPConnection object at 0x7f9709b4e520>: Failed to establish a new connection: [Errno 111] Connection refused'))
[2022-10-11 16:58:35,633][root.__registerBeatThreadRun():162] [ERROR] 服务心跳维持失败！
Traceback (most recent call last):
  File "/root/miniconda2/envs/netaxe/lib/python3.9/site-packages/urllib3/connection.py", line 169, in _new_conn
    conn = connection.create_connection(
  File "/root/miniconda2/envs/netaxe/lib/python3.9/site-packages/urllib3/util/connection.py", line 96, in create_connection
    raise err
  File "/root/miniconda2/envs/netaxe/lib/python3.9/site-packages/urllib3/util/connection.py", line 86, in create_connection
    sock.connect(sa)
ConnectionRefusedError: [Errno 111] Connection refused

During handling of the above exception, another exception occurred:

Traceback (most recent call last):
  File "/root/miniconda2/envs/netaxe/lib/python3.9/site-packages/urllib3/connectionpool.py", line 699, in urlopen
    httplib_response = self._make_request(
  File "/root/miniconda2/envs/netaxe/lib/python3.9/site-packages/urllib3/connectionpool.py", line 394, in _make_request
    conn.request(method, url, **httplib_request_kw)
  File "/root/miniconda2/envs/netaxe/lib/python3.9/site-packages/urllib3/connection.py", line 234, in request
    super(HTTPConnection, self).request(method, url, body=body, headers=headers)
  File "/root/miniconda2/envs/netaxe/lib/python3.9/http/client.py", line 1285, in request
    self._send_request(method, url, body, headers, encode_chunked)
  File "/root/miniconda2/envs/netaxe/lib/python3.9/http/client.py", line 1331, in _send_request
    self.endheaders(body, encode_chunked=encode_chunked)
  File "/root/miniconda2/envs/netaxe/lib/python3.9/http/client.py", line 1280, in endheaders
    self._send_output(message_body, encode_chunked=encode_chunked)
  File "/root/miniconda2/envs/netaxe/lib/python3.9/http/client.py", line 1040, in _send_output
    self.send(msg)
  File "/root/miniconda2/envs/netaxe/lib/python3.9/http/client.py", line 980, in send
    self.connect()
  File "/root/miniconda2/envs/netaxe/lib/python3.9/site-packages/urllib3/connection.py", line 200, in connect
    conn = self._new_conn()
  File "/root/miniconda2/envs/netaxe/lib/python3.9/site-packages/urllib3/connection.py", line 181, in _new_conn
    raise NewConnectionError(
urllib3.exceptions.NewConnectionError: <urllib3.connection.HTTPConnection object at 0x7f96fda1df70>: Failed to establish a new connection: [Errno 111] Connection refused

During handling of the above exception, another exception occurred:

Traceback (most recent call last):
  File "/root/miniconda2/envs/netaxe/lib/python3.9/site-packages/requests/adapters.py", line 489, in send
    resp = conn.urlopen(
  File "/root/miniconda2/envs/netaxe/lib/python3.9/site-packages/urllib3/connectionpool.py", line 755, in urlopen
    retries = retries.increment(
  File "/root/miniconda2/envs/netaxe/lib/python3.9/site-packages/urllib3/util/retry.py", line 574, in increment
    raise MaxRetryError(_pool, url, error or ResponseError(cause))
urllib3.exceptions.MaxRetryError: HTTPConnectionPool(host='10.254.2.188', port=8848): Max retries exceeded with url: /nacos/v1/ns/instance/beat?serviceName=auth&groupName=default&namespaceId=public&beat=%7B%22ip%22%3A%20%2210.254.2.188%22%2C%20%22port%22%3A%20%228001%22%2C%20%22serviceName%22%3A%20%22auth%22%2C%20%22metadata%22%3A%20%7B%7D%2C%20%22weight%22%3A%201%7D (Caused by NewConnectionError('<urllib3.connection.HTTPConnection object at 0x7f96fda1df70>: Failed to establish a new connection: [Errno 111] Connection refused'))

During handling of the above exception, another exception occurred:

Traceback (most recent call last):
  File "/root/miniconda2/envs/netaxe/lib/python3.9/site-packages/KcangNacos/nacos.py", line 153, in __registerBeatThreadRun
    re = requests.put(beatUrl[:-1])
  File "/root/miniconda2/envs/netaxe/lib/python3.9/site-packages/requests/api.py", line 130, in put
    return request("put", url, data=data, **kwargs)
  File "/root/miniconda2/envs/netaxe/lib/python3.9/site-packages/requests/api.py", line 59, in request
    return session.request(method=method, url=url, **kwargs)
  File "/root/miniconda2/envs/netaxe/lib/python3.9/site-packages/requests/sessions.py", line 587, in request
    resp = self.send(prep, **send_kwargs)
  File "/root/miniconda2/envs/netaxe/lib/python3.9/site-packages/requests/sessions.py", line 701, in send
    r = adapter.send(request, **kwargs)
  File "/root/miniconda2/envs/netaxe/lib/python3.9/site-packages/requests/adapters.py", line 565, in send
    raise ConnectionError(e, request=request)
requests.exceptions.ConnectionError: HTTPConnectionPool(host='10.254.2.188', port=8848): Max retries exceeded with url: /nacos/v1/ns/instance/beat?serviceName=auth&groupName=default&namespaceId=public&beat=%7B%22ip%22%3A%20%2210.254.2.188%22%2C%20%22port%22%3A%20%228001%22%2C%20%22serviceName%22%3A%20%22auth%22%2C%20%22metadata%22%3A%20%7B%7D%2C%20%22weight%22%3A%201%7D (Caused by NewConnectionError('<urllib3.connection.HTTPConnection object at 0x7f96fda1df70>: Failed to establish a new connection: [Errno 111] Connection refused'))
[2022-10-11 16:58:42,096][root.__registerBeatThreadRun():162] [ERROR] 服务心跳维持失败！
Traceback (most recent call last):
  File "/root/miniconda2/envs/netaxe/lib/python3.9/site-packages/urllib3/connection.py", line 169, in _new_conn
    conn = connection.create_connection(
  File "/root/miniconda2/envs/netaxe/lib/python3.9/site-packages/urllib3/util/connection.py", line 96, in create_connection
    raise err
  File "/root/miniconda2/envs/netaxe/lib/python3.9/site-packages/urllib3/util/connection.py", line 86, in create_connection
    sock.connect(sa)
ConnectionRefusedError: [Errno 111] Connection refused

During handling of the above exception, another exception occurred:

Traceback (most recent call last):
  File "/root/miniconda2/envs/netaxe/lib/python3.9/site-packages/urllib3/connectionpool.py", line 699, in urlopen
    httplib_response = self._make_request(
  File "/root/miniconda2/envs/netaxe/lib/python3.9/site-packages/urllib3/connectionpool.py", line 394, in _make_request
    conn.request(method, url, **httplib_request_kw)
  File "/root/miniconda2/envs/netaxe/lib/python3.9/site-packages/urllib3/connection.py", line 234, in request
    super(HTTPConnection, self).request(method, url, body=body, headers=headers)
  File "/root/miniconda2/envs/netaxe/lib/python3.9/http/client.py", line 1285, in request
    self._send_request(method, url, body, headers, encode_chunked)
  File "/root/miniconda2/envs/netaxe/lib/python3.9/http/client.py", line 1331, in _send_request
    self.endheaders(body, encode_chunked=encode_chunked)
  File "/root/miniconda2/envs/netaxe/lib/python3.9/http/client.py", line 1280, in endheaders
    self._send_output(message_body, encode_chunked=encode_chunked)
  File "/root/miniconda2/envs/netaxe/lib/python3.9/http/client.py", line 1040, in _send_output
    self.send(msg)
  File "/root/miniconda2/envs/netaxe/lib/python3.9/http/client.py", line 980, in send
    self.connect()
  File "/root/miniconda2/envs/netaxe/lib/python3.9/site-packages/urllib3/connection.py", line 200, in connect
    conn = self._new_conn()
  File "/root/miniconda2/envs/netaxe/lib/python3.9/site-packages/urllib3/connection.py", line 181, in _new_conn
    raise NewConnectionError(
urllib3.exceptions.NewConnectionError: <urllib3.connection.HTTPConnection object at 0x7fac9c44e850>: Failed to establish a new connection: [Errno 111] Connection refused

During handling of the above exception, another exception occurred:

Traceback (most recent call last):
  File "/root/miniconda2/envs/netaxe/lib/python3.9/site-packages/requests/adapters.py", line 489, in send
    resp = conn.urlopen(
  File "/root/miniconda2/envs/netaxe/lib/python3.9/site-packages/urllib3/connectionpool.py", line 755, in urlopen
    retries = retries.increment(
  File "/root/miniconda2/envs/netaxe/lib/python3.9/site-packages/urllib3/util/retry.py", line 574, in increment
    raise MaxRetryError(_pool, url, error or ResponseError(cause))
urllib3.exceptions.MaxRetryError: HTTPConnectionPool(host='10.254.2.188', port=8848): Max retries exceeded with url: /nacos/v1/ns/instance/beat?serviceName=auth&groupName=default&namespaceId=public&beat=%7B%22ip%22%3A%20%2210.254.2.188%22%2C%20%22port%22%3A%20%228001%22%2C%20%22serviceName%22%3A%20%22auth%22%2C%20%22metadata%22%3A%20%7B%7D%2C%20%22weight%22%3A%201%7D (Caused by NewConnectionError('<urllib3.connection.HTTPConnection object at 0x7fac9c44e850>: Failed to establish a new connection: [Errno 111] Connection refused'))

During handling of the above exception, another exception occurred:

Traceback (most recent call last):
  File "/root/miniconda2/envs/netaxe/lib/python3.9/site-packages/KcangNacos/nacos.py", line 153, in __registerBeatThreadRun
    re = requests.put(beatUrl[:-1])
  File "/root/miniconda2/envs/netaxe/lib/python3.9/site-packages/requests/api.py", line 130, in put
    return request("put", url, data=data, **kwargs)
  File "/root/miniconda2/envs/netaxe/lib/python3.9/site-packages/requests/api.py", line 59, in request
    return session.request(method=method, url=url, **kwargs)
  File "/root/miniconda2/envs/netaxe/lib/python3.9/site-packages/requests/sessions.py", line 587, in request
    resp = self.send(prep, **send_kwargs)
  File "/root/miniconda2/envs/netaxe/lib/python3.9/site-packages/requests/sessions.py", line 701, in send
    r = adapter.send(request, **kwargs)
  File "/root/miniconda2/envs/netaxe/lib/python3.9/site-packages/requests/adapters.py", line 565, in send
    raise ConnectionError(e, request=request)
requests.exceptions.ConnectionError: HTTPConnectionPool(host='10.254.2.188', port=8848): Max retries exceeded with url: /nacos/v1/ns/instance/beat?serviceName=auth&groupName=default&namespaceId=public&beat=%7B%22ip%22%3A%20%2210.254.2.188%22%2C%20%22port%22%3A%20%228001%22%2C%20%22serviceName%22%3A%20%22auth%22%2C%20%22metadata%22%3A%20%7B%7D%2C%20%22weight%22%3A%201%7D (Caused by NewConnectionError('<urllib3.connection.HTTPConnection object at 0x7fac9c44e850>: Failed to establish a new connection: [Errno 111] Connection refused'))
[2022-10-11 17:01:35,616][root.__registerBeatThreadRun():162] [ERROR] 服务心跳维持失败！
Traceback (most recent call last):
  File "/root/miniconda2/envs/netaxe/lib/python3.9/site-packages/urllib3/connection.py", line 169, in _new_conn
    conn = connection.create_connection(
  File "/root/miniconda2/envs/netaxe/lib/python3.9/site-packages/urllib3/util/connection.py", line 96, in create_connection
    raise err
  File "/root/miniconda2/envs/netaxe/lib/python3.9/site-packages/urllib3/util/connection.py", line 86, in create_connection
    sock.connect(sa)
ConnectionRefusedError: [Errno 111] Connection refused

During handling of the above exception, another exception occurred:

Traceback (most recent call last):
  File "/root/miniconda2/envs/netaxe/lib/python3.9/site-packages/urllib3/connectionpool.py", line 699, in urlopen
    httplib_response = self._make_request(
  File "/root/miniconda2/envs/netaxe/lib/python3.9/site-packages/urllib3/connectionpool.py", line 394, in _make_request
    conn.request(method, url, **httplib_request_kw)
  File "/root/miniconda2/envs/netaxe/lib/python3.9/site-packages/urllib3/connection.py", line 234, in request
    super(HTTPConnection, self).request(method, url, body=body, headers=headers)
  File "/root/miniconda2/envs/netaxe/lib/python3.9/http/client.py", line 1285, in request
    self._send_request(method, url, body, headers, encode_chunked)
  File "/root/miniconda2/envs/netaxe/lib/python3.9/http/client.py", line 1331, in _send_request
    self.endheaders(body, encode_chunked=encode_chunked)
  File "/root/miniconda2/envs/netaxe/lib/python3.9/http/client.py", line 1280, in endheaders
    self._send_output(message_body, encode_chunked=encode_chunked)
  File "/root/miniconda2/envs/netaxe/lib/python3.9/http/client.py", line 1040, in _send_output
    self.send(msg)
  File "/root/miniconda2/envs/netaxe/lib/python3.9/http/client.py", line 980, in send
    self.connect()
  File "/root/miniconda2/envs/netaxe/lib/python3.9/site-packages/urllib3/connection.py", line 200, in connect
    conn = self._new_conn()
  File "/root/miniconda2/envs/netaxe/lib/python3.9/site-packages/urllib3/connection.py", line 181, in _new_conn
    raise NewConnectionError(
urllib3.exceptions.NewConnectionError: <urllib3.connection.HTTPConnection object at 0x7fb873725340>: Failed to establish a new connection: [Errno 111] Connection refused

During handling of the above exception, another exception occurred:

Traceback (most recent call last):
  File "/root/miniconda2/envs/netaxe/lib/python3.9/site-packages/requests/adapters.py", line 489, in send
    resp = conn.urlopen(
  File "/root/miniconda2/envs/netaxe/lib/python3.9/site-packages/urllib3/connectionpool.py", line 755, in urlopen
    retries = retries.increment(
  File "/root/miniconda2/envs/netaxe/lib/python3.9/site-packages/urllib3/util/retry.py", line 574, in increment
    raise MaxRetryError(_pool, url, error or ResponseError(cause))
urllib3.exceptions.MaxRetryError: HTTPConnectionPool(host='10.254.2.188', port=8848): Max retries exceeded with url: /nacos/v1/ns/instance/beat?serviceName=auth&groupName=default&namespaceId=public&beat=%7B%22ip%22%3A%20%2210.254.2.188%22%2C%20%22port%22%3A%20%228001%22%2C%20%22serviceName%22%3A%20%22auth%22%2C%20%22metadata%22%3A%20%7B%7D%2C%20%22weight%22%3A%201%7D (Caused by NewConnectionError('<urllib3.connection.HTTPConnection object at 0x7fb873725340>: Failed to establish a new connection: [Errno 111] Connection refused'))

During handling of the above exception, another exception occurred:

Traceback (most recent call last):
  File "/root/miniconda2/envs/netaxe/lib/python3.9/site-packages/KcangNacos/nacos.py", line 153, in __registerBeatThreadRun
    re = requests.put(beatUrl[:-1])
  File "/root/miniconda2/envs/netaxe/lib/python3.9/site-packages/requests/api.py", line 130, in put
    return request("put", url, data=data, **kwargs)
  File "/root/miniconda2/envs/netaxe/lib/python3.9/site-packages/requests/api.py", line 59, in request
    return session.request(method=method, url=url, **kwargs)
  File "/root/miniconda2/envs/netaxe/lib/python3.9/site-packages/requests/sessions.py", line 587, in request
    resp = self.send(prep, **send_kwargs)
  File "/root/miniconda2/envs/netaxe/lib/python3.9/site-packages/requests/sessions.py", line 701, in send
    r = adapter.send(request, **kwargs)
  File "/root/miniconda2/envs/netaxe/lib/python3.9/site-packages/requests/adapters.py", line 565, in send
    raise ConnectionError(e, request=request)
requests.exceptions.ConnectionError: HTTPConnectionPool(host='10.254.2.188', port=8848): Max retries exceeded with url: /nacos/v1/ns/instance/beat?serviceName=auth&groupName=default&namespaceId=public&beat=%7B%22ip%22%3A%20%2210.254.2.188%22%2C%20%22port%22%3A%20%228001%22%2C%20%22serviceName%22%3A%20%22auth%22%2C%20%22metadata%22%3A%20%7B%7D%2C%20%22weight%22%3A%201%7D (Caused by NewConnectionError('<urllib3.connection.HTTPConnection object at 0x7fb873725340>: Failed to establish a new connection: [Errno 111] Connection refused'))
[2022-10-11 17:01:35,616][root.__registerBeatThreadRun():162] [ERROR] 服务心跳维持失败！
Traceback (most recent call last):
  File "/root/miniconda2/envs/netaxe/lib/python3.9/site-packages/urllib3/connection.py", line 169, in _new_conn
    conn = connection.create_connection(
  File "/root/miniconda2/envs/netaxe/lib/python3.9/site-packages/urllib3/util/connection.py", line 96, in create_connection
    raise err
  File "/root/miniconda2/envs/netaxe/lib/python3.9/site-packages/urllib3/util/connection.py", line 86, in create_connection
    sock.connect(sa)
ConnectionRefusedError: [Errno 111] Connection refused

During handling of the above exception, another exception occurred:

Traceback (most recent call last):
  File "/root/miniconda2/envs/netaxe/lib/python3.9/site-packages/urllib3/connectionpool.py", line 699, in urlopen
    httplib_response = self._make_request(
  File "/root/miniconda2/envs/netaxe/lib/python3.9/site-packages/urllib3/connectionpool.py", line 394, in _make_request
    conn.request(method, url, **httplib_request_kw)
  File "/root/miniconda2/envs/netaxe/lib/python3.9/site-packages/urllib3/connection.py", line 234, in request
    super(HTTPConnection, self).request(method, url, body=body, headers=headers)
  File "/root/miniconda2/envs/netaxe/lib/python3.9/http/client.py", line 1285, in request
    self._send_request(method, url, body, headers, encode_chunked)
  File "/root/miniconda2/envs/netaxe/lib/python3.9/http/client.py", line 1331, in _send_request
    self.endheaders(body, encode_chunked=encode_chunked)
  File "/root/miniconda2/envs/netaxe/lib/python3.9/http/client.py", line 1280, in endheaders
    self._send_output(message_body, encode_chunked=encode_chunked)
  File "/root/miniconda2/envs/netaxe/lib/python3.9/http/client.py", line 1040, in _send_output
    self.send(msg)
  File "/root/miniconda2/envs/netaxe/lib/python3.9/http/client.py", line 980, in send
    self.connect()
  File "/root/miniconda2/envs/netaxe/lib/python3.9/site-packages/urllib3/connection.py", line 200, in connect
    conn = self._new_conn()
  File "/root/miniconda2/envs/netaxe/lib/python3.9/site-packages/urllib3/connection.py", line 181, in _new_conn
    raise NewConnectionError(
urllib3.exceptions.NewConnectionError: <urllib3.connection.HTTPConnection object at 0x7fb87379c820>: Failed to establish a new connection: [Errno 111] Connection refused

During handling of the above exception, another exception occurred:

Traceback (most recent call last):
  File "/root/miniconda2/envs/netaxe/lib/python3.9/site-packages/requests/adapters.py", line 489, in send
    resp = conn.urlopen(
  File "/root/miniconda2/envs/netaxe/lib/python3.9/site-packages/urllib3/connectionpool.py", line 755, in urlopen
    retries = retries.increment(
  File "/root/miniconda2/envs/netaxe/lib/python3.9/site-packages/urllib3/util/retry.py", line 574, in increment
    raise MaxRetryError(_pool, url, error or ResponseError(cause))
urllib3.exceptions.MaxRetryError: HTTPConnectionPool(host='10.254.2.188', port=8848): Max retries exceeded with url: /nacos/v1/ns/instance/beat?serviceName=auth&groupName=default&namespaceId=public&beat=%7B%22ip%22%3A%20%2210.254.2.188%22%2C%20%22port%22%3A%20%228001%22%2C%20%22serviceName%22%3A%20%22auth%22%2C%20%22metadata%22%3A%20%7B%7D%2C%20%22weight%22%3A%201%7D (Caused by NewConnectionError('<urllib3.connection.HTTPConnection object at 0x7fb87379c820>: Failed to establish a new connection: [Errno 111] Connection refused'))

During handling of the above exception, another exception occurred:

Traceback (most recent call last):
  File "/root/miniconda2/envs/netaxe/lib/python3.9/site-packages/KcangNacos/nacos.py", line 153, in __registerBeatThreadRun
    re = requests.put(beatUrl[:-1])
  File "/root/miniconda2/envs/netaxe/lib/python3.9/site-packages/requests/api.py", line 130, in put
    return request("put", url, data=data, **kwargs)
  File "/root/miniconda2/envs/netaxe/lib/python3.9/site-packages/requests/api.py", line 59, in request
    return session.request(method=method, url=url, **kwargs)
  File "/root/miniconda2/envs/netaxe/lib/python3.9/site-packages/requests/sessions.py", line 587, in request
    resp = self.send(prep, **send_kwargs)
  File "/root/miniconda2/envs/netaxe/lib/python3.9/site-packages/requests/sessions.py", line 701, in send
    r = adapter.send(request, **kwargs)
  File "/root/miniconda2/envs/netaxe/lib/python3.9/site-packages/requests/adapters.py", line 565, in send
    raise ConnectionError(e, request=request)
requests.exceptions.ConnectionError: HTTPConnectionPool(host='10.254.2.188', port=8848): Max retries exceeded with url: /nacos/v1/ns/instance/beat?serviceName=auth&groupName=default&namespaceId=public&beat=%7B%22ip%22%3A%20%2210.254.2.188%22%2C%20%22port%22%3A%20%228001%22%2C%20%22serviceName%22%3A%20%22auth%22%2C%20%22metadata%22%3A%20%7B%7D%2C%20%22weight%22%3A%201%7D (Caused by NewConnectionError('<urllib3.connection.HTTPConnection object at 0x7fb87379c820>: Failed to establish a new connection: [Errno 111] Connection refused'))
[2022-10-11 17:11:21,724][root.__registerBeatThreadRun():162] [ERROR] 服务心跳维持失败！
Traceback (most recent call last):
  File "/root/miniconda2/envs/netaxe/lib/python3.9/site-packages/urllib3/connection.py", line 169, in _new_conn
    conn = connection.create_connection(
  File "/root/miniconda2/envs/netaxe/lib/python3.9/site-packages/urllib3/util/connection.py", line 96, in create_connection
    raise err
  File "/root/miniconda2/envs/netaxe/lib/python3.9/site-packages/urllib3/util/connection.py", line 86, in create_connection
    sock.connect(sa)
ConnectionRefusedError: [Errno 111] Connection refused

During handling of the above exception, another exception occurred:

Traceback (most recent call last):
  File "/root/miniconda2/envs/netaxe/lib/python3.9/site-packages/urllib3/connectionpool.py", line 699, in urlopen
    httplib_response = self._make_request(
  File "/root/miniconda2/envs/netaxe/lib/python3.9/site-packages/urllib3/connectionpool.py", line 394, in _make_request
    conn.request(method, url, **httplib_request_kw)
  File "/root/miniconda2/envs/netaxe/lib/python3.9/site-packages/urllib3/connection.py", line 234, in request
    super(HTTPConnection, self).request(method, url, body=body, headers=headers)
  File "/root/miniconda2/envs/netaxe/lib/python3.9/http/client.py", line 1285, in request
    self._send_request(method, url, body, headers, encode_chunked)
  File "/root/miniconda2/envs/netaxe/lib/python3.9/http/client.py", line 1331, in _send_request
    self.endheaders(body, encode_chunked=encode_chunked)
  File "/root/miniconda2/envs/netaxe/lib/python3.9/http/client.py", line 1280, in endheaders
    self._send_output(message_body, encode_chunked=encode_chunked)
  File "/root/miniconda2/envs/netaxe/lib/python3.9/http/client.py", line 1040, in _send_output
    self.send(msg)
  File "/root/miniconda2/envs/netaxe/lib/python3.9/http/client.py", line 980, in send
    self.connect()
  File "/root/miniconda2/envs/netaxe/lib/python3.9/site-packages/urllib3/connection.py", line 200, in connect
    conn = self._new_conn()
  File "/root/miniconda2/envs/netaxe/lib/python3.9/site-packages/urllib3/connection.py", line 181, in _new_conn
    raise NewConnectionError(
urllib3.exceptions.NewConnectionError: <urllib3.connection.HTTPConnection object at 0x7f1369b8edc0>: Failed to establish a new connection: [Errno 111] Connection refused

During handling of the above exception, another exception occurred:

Traceback (most recent call last):
  File "/root/miniconda2/envs/netaxe/lib/python3.9/site-packages/requests/adapters.py", line 489, in send
    resp = conn.urlopen(
  File "/root/miniconda2/envs/netaxe/lib/python3.9/site-packages/urllib3/connectionpool.py", line 755, in urlopen
    retries = retries.increment(
  File "/root/miniconda2/envs/netaxe/lib/python3.9/site-packages/urllib3/util/retry.py", line 574, in increment
    raise MaxRetryError(_pool, url, error or ResponseError(cause))
urllib3.exceptions.MaxRetryError: HTTPConnectionPool(host='10.254.2.188', port=8848): Max retries exceeded with url: /nacos/v1/ns/instance/beat?serviceName=auth&groupName=default&namespaceId=public&beat=%7B%22ip%22%3A%20%2210.254.2.188%22%2C%20%22port%22%3A%20%228001%22%2C%20%22serviceName%22%3A%20%22auth%22%2C%20%22metadata%22%3A%20%7B%7D%2C%20%22weight%22%3A%201%7D (Caused by NewConnectionError('<urllib3.connection.HTTPConnection object at 0x7f1369b8edc0>: Failed to establish a new connection: [Errno 111] Connection refused'))

During handling of the above exception, another exception occurred:

Traceback (most recent call last):
  File "/root/miniconda2/envs/netaxe/lib/python3.9/site-packages/KcangNacos/nacos.py", line 153, in __registerBeatThreadRun
    re = requests.put(beatUrl[:-1])
  File "/root/miniconda2/envs/netaxe/lib/python3.9/site-packages/requests/api.py", line 130, in put
    return request("put", url, data=data, **kwargs)
  File "/root/miniconda2/envs/netaxe/lib/python3.9/site-packages/requests/api.py", line 59, in request
    return session.request(method=method, url=url, **kwargs)
  File "/root/miniconda2/envs/netaxe/lib/python3.9/site-packages/requests/sessions.py", line 587, in request
    resp = self.send(prep, **send_kwargs)
  File "/root/miniconda2/envs/netaxe/lib/python3.9/site-packages/requests/sessions.py", line 701, in send
    r = adapter.send(request, **kwargs)
  File "/root/miniconda2/envs/netaxe/lib/python3.9/site-packages/requests/adapters.py", line 565, in send
    raise ConnectionError(e, request=request)
requests.exceptions.ConnectionError: HTTPConnectionPool(host='10.254.2.188', port=8848): Max retries exceeded with url: /nacos/v1/ns/instance/beat?serviceName=auth&groupName=default&namespaceId=public&beat=%7B%22ip%22%3A%20%2210.254.2.188%22%2C%20%22port%22%3A%20%228001%22%2C%20%22serviceName%22%3A%20%22auth%22%2C%20%22metadata%22%3A%20%7B%7D%2C%20%22weight%22%3A%201%7D (Caused by NewConnectionError('<urllib3.connection.HTTPConnection object at 0x7f1369b8edc0>: Failed to establish a new connection: [Errno 111] Connection refused'))
[2022-10-11 17:11:21,729][root.__registerBeatThreadRun():162] [ERROR] 服务心跳维持失败！
Traceback (most recent call last):
  File "/root/miniconda2/envs/netaxe/lib/python3.9/site-packages/urllib3/connection.py", line 169, in _new_conn
    conn = connection.create_connection(
  File "/root/miniconda2/envs/netaxe/lib/python3.9/site-packages/urllib3/util/connection.py", line 96, in create_connection
    raise err
  File "/root/miniconda2/envs/netaxe/lib/python3.9/site-packages/urllib3/util/connection.py", line 86, in create_connection
    sock.connect(sa)
ConnectionRefusedError: [Errno 111] Connection refused

During handling of the above exception, another exception occurred:

Traceback (most recent call last):
  File "/root/miniconda2/envs/netaxe/lib/python3.9/site-packages/urllib3/connectionpool.py", line 699, in urlopen
    httplib_response = self._make_request(
  File "/root/miniconda2/envs/netaxe/lib/python3.9/site-packages/urllib3/connectionpool.py", line 394, in _make_request
    conn.request(method, url, **httplib_request_kw)
  File "/root/miniconda2/envs/netaxe/lib/python3.9/site-packages/urllib3/connection.py", line 234, in request
    super(HTTPConnection, self).request(method, url, body=body, headers=headers)
  File "/root/miniconda2/envs/netaxe/lib/python3.9/http/client.py", line 1285, in request
    self._send_request(method, url, body, headers, encode_chunked)
  File "/root/miniconda2/envs/netaxe/lib/python3.9/http/client.py", line 1331, in _send_request
    self.endheaders(body, encode_chunked=encode_chunked)
  File "/root/miniconda2/envs/netaxe/lib/python3.9/http/client.py", line 1280, in endheaders
    self._send_output(message_body, encode_chunked=encode_chunked)
  File "/root/miniconda2/envs/netaxe/lib/python3.9/http/client.py", line 1040, in _send_output
    self.send(msg)
  File "/root/miniconda2/envs/netaxe/lib/python3.9/http/client.py", line 980, in send
    self.connect()
  File "/root/miniconda2/envs/netaxe/lib/python3.9/site-packages/urllib3/connection.py", line 200, in connect
    conn = self._new_conn()
  File "/root/miniconda2/envs/netaxe/lib/python3.9/site-packages/urllib3/connection.py", line 181, in _new_conn
    raise NewConnectionError(
urllib3.exceptions.NewConnectionError: <urllib3.connection.HTTPConnection object at 0x7f136b405670>: Failed to establish a new connection: [Errno 111] Connection refused

During handling of the above exception, another exception occurred:

Traceback (most recent call last):
  File "/root/miniconda2/envs/netaxe/lib/python3.9/site-packages/requests/adapters.py", line 489, in send
    resp = conn.urlopen(
  File "/root/miniconda2/envs/netaxe/lib/python3.9/site-packages/urllib3/connectionpool.py", line 755, in urlopen
    retries = retries.increment(
  File "/root/miniconda2/envs/netaxe/lib/python3.9/site-packages/urllib3/util/retry.py", line 574, in increment
    raise MaxRetryError(_pool, url, error or ResponseError(cause))
urllib3.exceptions.MaxRetryError: HTTPConnectionPool(host='10.254.2.188', port=8848): Max retries exceeded with url: /nacos/v1/ns/instance/beat?serviceName=auth&groupName=default&namespaceId=public&beat=%7B%22ip%22%3A%20%2210.254.2.188%22%2C%20%22port%22%3A%20%228001%22%2C%20%22serviceName%22%3A%20%22auth%22%2C%20%22metadata%22%3A%20%7B%7D%2C%20%22weight%22%3A%201%7D (Caused by NewConnectionError('<urllib3.connection.HTTPConnection object at 0x7f136b405670>: Failed to establish a new connection: [Errno 111] Connection refused'))

During handling of the above exception, another exception occurred:

Traceback (most recent call last):
  File "/root/miniconda2/envs/netaxe/lib/python3.9/site-packages/KcangNacos/nacos.py", line 153, in __registerBeatThreadRun
    re = requests.put(beatUrl[:-1])
  File "/root/miniconda2/envs/netaxe/lib/python3.9/site-packages/requests/api.py", line 130, in put
    return request("put", url, data=data, **kwargs)
  File "/root/miniconda2/envs/netaxe/lib/python3.9/site-packages/requests/api.py", line 59, in request
    return session.request(method=method, url=url, **kwargs)
  File "/root/miniconda2/envs/netaxe/lib/python3.9/site-packages/requests/sessions.py", line 587, in request
    resp = self.send(prep, **send_kwargs)
  File "/root/miniconda2/envs/netaxe/lib/python3.9/site-packages/requests/sessions.py", line 701, in send
    r = adapter.send(request, **kwargs)
  File "/root/miniconda2/envs/netaxe/lib/python3.9/site-packages/requests/adapters.py", line 565, in send
    raise ConnectionError(e, request=request)
requests.exceptions.ConnectionError: HTTPConnectionPool(host='10.254.2.188', port=8848): Max retries exceeded with url: /nacos/v1/ns/instance/beat?serviceName=auth&groupName=default&namespaceId=public&beat=%7B%22ip%22%3A%20%2210.254.2.188%22%2C%20%22port%22%3A%20%228001%22%2C%20%22serviceName%22%3A%20%22auth%22%2C%20%22metadata%22%3A%20%7B%7D%2C%20%22weight%22%3A%201%7D (Caused by NewConnectionError('<urllib3.connection.HTTPConnection object at 0x7f136b405670>: Failed to establish a new connection: [Errno 111] Connection refused'))
